Workbook
Name KEY_Pri: [1]KEY!$D$3:$D$6
Name KEY_Pri: KEY!$D$3:$D$6
Name KEY_Tier: [1]KEY!$A$3:$A$7
Name KEY_Tier: KEY!$A$3:$A$7
Name TargetMaturityTier: COVER!$F$13
Name TargetMaturityTier: COVER!$F$13

Sheet COVER
E2: NIST CSF GAP ASSESSMENT
E3: Febuary 2021
E11: Prepared for: | F11: Friendship Community Care
E12: Prepared by: | F12: Edafio Cybersecurity
E13: Target Maturity Level: | F13: 3

Sheet Assessment
A1: Sort | B1: Function | C1: Function Desc. | D1: Category | E1: Category Desc. | F1: Subcategory | G1: SubCategory Desc. | H1: Discussion Elements | I1: Interview Grouping | J1: Assessor Notes | K1: Finding | L1: Assessed Tier | M1: Priority | N1: Ref: CIS | O1: Ref: ISO | P1: Ref: 800-53 R4 | Q1: Ref: HIPAA | R1: Ref: HITRUST | S1: Ref: COBIT 5
A2: 1.1.1 | B2: ID | C2: Identify | D2: AM | E2: Asset Management (ID.AM): The data, personnel, devices, systems, and facilities that enable the organization to achieve business purposes are identified and managed consistent with their relative importance to organizational objectives and the organization’s risk strategy. | F2: ID.AM-1 | G2: Physical devices and systems within the organization are inventoried | H2: AD, *IX, Network Devices, IoT (Printers) | I2: Infrastructure | K2: While the CLIENT has key monitoring and management software (e.g., ManageEngine, PRTG, vCenter) that contains elements of inventory management, these systems are not leveraged in an intentional manner to ensure a comprehensive inventory is maintained. | L2: 1 | M2: Medium | N2: CIS CSC 1 | O2: A.8.1.1, A.8.1.2 | P2: CM-8, PM-5 | Q2: 45 C.F.R. §§ 164.308(a)(1)(ii)(A), 164.310(a)(2)(ii), 164.310(d) | S2: BAI09.01, BAI09.02
A3: 1.1.2 | B3: ID | C3: Identify | D3: AM | E3: Asset Management (ID.AM): The data, personnel, devices, systems, and facilities that enable the organization to achieve business purposes are identified and managed consistent with their relative importance to organizational objectives and the organization’s risk strategy. | F3: ID.AM-2 | G3: Software platforms and applications within the organization are inventoried | I3: Infrastructure | K3: The CLIENT leverages ManageEngine and vCenter to provide appropriate visibility to software platforms and applications. Specific software can be polled and patches can be deployed. | L3: 2 | M3: Medium | N3: CIS CSC 2 | O3: A.8.1.1, A.8.1.2 | P3: CM-8, PM-5 | Q3: 45 C.F.R. §§ 164.308(a)(1)(ii)(A), 164.308(a)(7)(ii)(E ) | S3: BAI09.01, BAI09.02, BAI09.05
A4: 1.1.3 | B4: ID | C4: Identify | D4: AM | E4: Asset Management (ID.AM): The data, personnel, devices, systems, and facilities that enable the organization to achieve business purposes are identified and managed consistent with their relative importance to organizational objectives and the organization’s risk strategy. | F4: ID.AM-3 | G4: Organizational communication and data flows are mapped | H4: Organization Charts, Network Diagrams, Data Flor Charts | I4: GRC | K4: No Network Diagrams, Data Flows, or Organizational contact sheets exist. An org chart was recently updated (Jan 2021) but it is not distributed to the organization and some members were note aware of its existence. | L4: 1 | M4: High | N4: CIS CSC 12 | O4: A.13.2.1 | P4: AC-4, CA-3, CA-9, PL-8 | Q4: 45 C.F.R. §§ 164.308(a)(1)(ii)(A), 164.308(a)(3)(ii)(A), 164.308(a)(8), 164.310(d) | S4: DSS05.02
A5: 1.1.4 | B5: ID | C5: Identify | D5: AM | E5: Asset Management (ID.AM): The data, personnel, devices, systems, and facilities that enable the organization to achieve business purposes are identified and managed consistent with their relative importance to organizational objectives and the organization’s risk strategy. | F5: ID.AM-4 | G5: External information systems are catalogued | H5: Hosted and Cloud Public Facing | I5: Infrastructure | K5: The CLIENT does have a technical document that lists key SAAS/Cloud Vendors. The location was not readily known and there are not process to ensure that it is comprehensive and maintained. | L5: 2 | M5: Low | N5: CIS CSC 12 | O5: A.11.2.6 | P5: AC-20, SA-9 | Q5: 45 C.F.R. §§ 164.308(a)(4)(ii)(A), 164.308(b), 164.314(a)(1), 164.314(a)(2)(i)(B), 164.314(a)(2)(ii), 164.316(b)(2) | S5: APO02.02
A6: 1.1.5 | B6: ID | C6: Identify | D6: AM | E6: Asset Management (ID.AM): The data, personnel, devices, systems, and facilities that enable the organization to achieve business purposes are identified and managed consistent with their relative importance to organizational objectives and the organization’s risk strategy. | F6: ID.AM-5 | G6: Resources (e.g., hardware, devices, data, time, personnel, and software) are prioritized based on their classification, criticality, and business value | H6: Critical Services | I6: GRC | K6: Critical services are not defined and there has been no identifiable effort to label or document assets that support their services. | L6: 1 | M6: Medium | N6: CIS CSC 13, 14 | O6: A.8.2.1 | P6: CP-2, RA-2, SA-14, SC-6 | Q6: 45 C.F.R. § 164.308(a)(7)(ii)(E ) | S6: APO03.03, APO03.04, BAI09.02
A7: 1.1.6 | B7: ID | C7: Identify | D7: AM | E7: Asset Management (ID.AM): The data, personnel, devices, systems, and facilities that enable the organization to achieve business purposes are identified and managed consistent with their relative importance to organizational objectives and the organization’s risk strategy. | F7: ID.AM-6 | G7: Cybersecurity roles and responsibilities for the entire workforce and third-party stakeholders (e.g., suppliers, customers, partners) are established | H7: BAAs | I7: GRC | K7: Roles and responsibilities for Third-Parties are expressed contractually via BAAs. No roles and responsibilities for employees exist. | L7: 1 | M7: High | N7: CIS CSC 17, 19 | O7: A.6.1.1 | P7: CP-2, PS-7, PM-11 | Q7: 45 C.F.R. §§ 164.308(a)(2), 164.308(a)(3), 164.308(a)(4), 164.308(b)(1), 164.314 | S7: APO01.02, DSS06.03
A8: 1.2.1 | B8: ID | C8: Identify | D8: BE | E8: Business Environment (ID.BE): The organization’s mission, objectives, stakeholders, and activities are understood and prioritized; this information is used to inform cybersecurity roles, responsibilities, and risk management decisions. | F8: ID.BE-1 | G8: The organization’s role in the supply chain is identified and communicated | H8: Vendor Risk Management | I8: GRC | K8: They do have BAAs on file. However, there is little process to ensure that a BAA is initiated. There is NO process to perform initial risk assessments or ongoing risk reviews. | L8: 2 | M8: Medium | O8: A.15.1.3, A.15.2.1, A.15.2.2 | P8: CP-2, SA-12 | Q8: 45 C.F.R. §§ 164.308(a)(1)(ii)(A), 164.308(a)(4)(ii), 164.308(a)(7)(ii)(C), 164.308(a)(7)(ii)(E), 164.308(a)(8), 164.310(a)(2)(i), 164.314, 164.316 | S8: APO08.04, APO08.05, APO10.03, APO10.04, APO10.05
A9: 1.2.2 | B9: ID | C9: Identify | D9: BE | E9: Business Environment (ID.BE): The organization’s mission, objectives, stakeholders, and activities are understood and prioritized; this information is used to inform cybersecurity roles, responsibilities, and risk management decisions. | F9: ID.BE-2 | G9: The organization’s place in critical infrastructure and its industry sector is identified and communicated | I9: GRC | K9: The CLIENT has situational awareness of their place in critical infrastructure. However, there is a lack of using this knowledge to inform their Risk Management processes. | L9: 2 | M9: Medium | P9: PM-8 | Q9: 45 C.F.R. §§ 164.308(a)(1)(ii)(A), 164.308(a)(4)(ii), 164.308(a)(7)(ii)(C), 164.308(a)(7)(ii)(E), 164.308(a)(8), 164.310(a)(2)(i), 164.314, 164.316 | S9: APO02.06, APO03.01
A10: 1.2.3 | B10: ID | C10: Identify | D10: BE | E10: Business Environment (ID.BE): The organization’s mission, objectives, stakeholders, and activities are understood and prioritized; this information is used to inform cybersecurity roles, responsibilities, and risk management decisions. | F10: ID.BE-3 | G10: Priorities for organizational mission, objectives, and activities are established and communicated | H10: Steering Committees | I10: GRC | K10: The CLIENT's overall mission, goals, and objectives are established by Executive Team and communicated with Directors, and then to Sr. Staff. | L10: 2 | M10: Low | P10: PM-11, SA-14 | Q10: 45 C.F.R. §§ 164.308(a)(7)(ii)(B), 164.308(a)(7)(ii)(C), 164.308(a)(7)(ii)(D),164.308(a)(7)(ii)(E), 164.310(a)(2)(i), 164.316 | S10: APO02.01, APO02.06, APO03.01
A11: 1.2.4 | B11: ID | C11: Identify | D11: BE | E11: Business Environment (ID.BE): The organization’s mission, objectives, stakeholders, and activities are understood and prioritized; this information is used to inform cybersecurity roles, responsibilities, and risk management decisions. | F11: ID.BE-4 | G11: Dependencies and critical functions for delivery of critical services are established | I11: Data | K11: Critical services and functions have not been defined. | L11: 1 | M11: Low | O11: A.11.2.2, A.11.2.3, A.12.1.3 | P11: CP-8, PE-9, PE-11, PM-8, SA-14 | Q11: 45 C.F.R. §§ 164.308(a)(7)(i), 164.308.(a)(7)(ii)(E), 164.310(a)(2)(i), 164.312(a)(2)(ii), 164.314(a)(1), 164.314(b)(2)(i)
A12: 1.2.5 | B12: ID | C12: Identify | D12: BE | E12: Business Environment (ID.BE): The organization’s mission, objectives, stakeholders, and activities are understood and prioritized; this information is used to inform cybersecurity roles, responsibilities, and risk management decisions. | F12: ID.BE-5 | G12: Resilience requirements to support delivery of critical services are established for all operating states (e.g. under duress/attack, during recovery, normal operations) | I12: Data | K12: Resilience requirements and/or thresholds have not been determined. This increases the risk of an ill-suited response during a continuity or security event. | L12: 1 | M12: Low | O12: A.11.1.4, A.17.1.1, A.17.1.2, A.17.2.1 | P12: CP-2, CP-11, SA-13, SA-14 | Q12: 45 C.F.R. §§ 164.308(a)(1)(ii)(B), 164.308(a)(6)(ii), 164.308(a)(7), 164.308(a)(8), 164.310(a)(2)(i), 164.312(a)(2)(ii), 164.314(b)(2)(i) | S12: DSS04.02
A13: 1.3.1 | B13: ID | C13: Identify | D13: GV | E13: Governance (ID.GV): The policies, procedures, and processes to manage and monitor the organization’s regulatory, legal, risk, environmental, and operational requirements are understood and inform the management of cybersecurity risk. | F13: ID.GV-1 | G13: Organizational cybersecurity policy is established and communicated | I13: GRC | K13: The CLIENT's Information Security Policy is woefully out dated, not maintained, and not disseminated for education. | L13: 1 | M13: High | N13: CIS CSC 19 | O13: A.5.1.1 | P13: -1 controls from all security control families | Q13: 45 C.F.R. §§ 164.308(a)(1)(i), 164.316 | S13: APO01.03, EDM01.01, EDM01.02
A14: 1.3.2 | B14: ID | C14: Identify | D14: GV | E14: Governance (ID.GV): The policies, procedures, and processes to manage and monitor the organization’s regulatory, legal, risk, environmental, and operational requirements are understood and inform the management of cybersecurity risk. | F14: ID.GV-2 | G14: Cybersecurity roles and responsibilities are coordinated and aligned with internal roles and external partners | I14: GRC | K14: The CLIENT does utilize an IT/Security Partner to response to Security Incidents. However, this is not outlined in an IR Plan or codified via contract. There are no roles and responsibilities for IS Program Management or Risk Assessment defined. | L14: 2 | M14: High | N14: CIS CSC 19 | O14: A.6.1.1, A.7.2.1 | P14: PS-7, PM-1, PM-2 | Q14: 45 C.F.R. §§ 164.308(a)(1)(i), 164.308(a)(2), 164.308(a)(3), 164.308(a)(4), 164.308(b), 164.314 | S14: APO13.12
A15: 1.3.3 | B15: ID | C15: Identify | D15: GV | E15: Governance (ID.GV): The policies, procedures, and processes to manage and monitor the organization’s regulatory, legal, risk, environmental, and operational requirements are understood and inform the management of cybersecurity risk. | F15: ID.GV-3 | G15: Legal and regulatory requirements regarding cybersecurity, including privacy and civil liberties obligations, are understood and managed | H15: Compliance | I15: GRC | K15: The CLIENT does understand its HIPAA regulatory obligations and have made significant progress in recent months to enhance its understanding and compliance. However, significant obligations are note met or managed at this time. | L15: 2 | M15: High | N15: CIS CSC 19 | O15: A.18.1 | P15: -1 controls from all security control families | Q15: 45 C.F.R. §§ 164.306, 164.308, 164.310, 164.312, 164.314, 164.316 | S15: MEA03.01, MEA03.04
A16: 1.3.4 | B16: ID | C16: Identify | D16: GV | E16: Governance (ID.GV): The policies, procedures, and processes to manage and monitor the organization’s regulatory, legal, risk, environmental, and operational requirements are understood and inform the management of cybersecurity risk. | F16: ID.GV-4 | G16: Governance and risk management processes address cybersecurity risks | H16: Risk Management | I16: GRC | K16: The CLIENT does not have any formalized plan or process for risk management. It is ad-hoc and reactive in nature. | L16: 1 | M16: High | P16: SA-2, PM-3, PM-7, PM-9, PM-10, PM-11 | Q16: 45 C.F.R. §§ 164.308(a)(1), 164.308(b) | S16: DSS04.02
A17: 1.4.1 | B17: ID | C17: Identify | D17: RA | E17: Risk Assessment (ID.RA): The organization understands the cybersecurity risk to organizational operations (including mission, functions, image, or reputation), organizational assets, and individuals. | F17: ID.RA-1 | G17: Asset vulnerabilities are identified and documented | H17: Vulnerability Scanning Formal Asset List/Type | I17: Security Controls | K17: Vulnerabilities related to Microsoft OS are identified and addressed via ManageEngine. No vulnerability scanning, reporting, or documentation is present. | L17: 2 | M17: High | N17: CIS CSC 4 | O17: A.12.6.1, A.18.2.3 | P17: CA-2, CA-7, CA-8, RA-3, RA-5, SA-5, SA-11, SI-2, SI-4, SI-5 | Q17: 45 C.F.R. §§ 164.308(a)(1)(ii)(A), 164.308(a)(7)(ii)(E), 164.308(a)(8), 164.310(a)(1), 164.312(a)(1), 164.316(b)(2)(iii) | S17: APO12.01, APO12.02, APO12.03, APO12.04
A18: 1.4.2 | B18: ID | C18: Identify | D18: RA | E18: Risk Assessment (ID.RA): The organization understands the cybersecurity risk to organizational operations (including mission, functions, image, or reputation), organizational assets, and individuals. | F18: ID.RA-2 | G18: Cyber threat intelligence is received from information sharing forums and sources. | I18: Security Controls | K18: Threat intelligence is received by the CLIENT's IT partner and via a CIO peer group. There is not an intentional or sustained effort to receive alerts via supply chain or authorities. | L18: 1 | M18: Medium | N18: CIS CSC 4 | O18: A.6.1.4 | P18: SI-5, PM-15, PM-16
A19: 1.4.3 | B19: ID | C19: Identify | D19: RA | E19: Risk Assessment (ID.RA): The organization understands the cybersecurity risk to organizational operations (including mission, functions, image, or reputation), organizational assets, and individuals. | F19: ID.RA-3 | G19: Threats, both internal and external, are identified and documented | H19: Pentesting | I19: Security Controls | K19: Risk assessments have been limited in scope and performed irregularly. There is a lack of documented follow-through of any risks identified outside IT operational tickets. | L19: 1 | M19: High | N19: CIS CSC 4 | P19: RA-3, SI-5, PM-12, PM-16 | Q19: 45 C.F.R. §§ 164.308(a)(1)(ii)(A),164.308(a)(1)(ii)(D), 164.308(a)(3), 164.308(a)(4), 164.308(a)(5)(ii)(A),164.310(a)(1), 164.310(a)(2)(iii), 164.312(a)(1), 164.312(c), 164.312(e), 164.314, 164.316 | S19: APO12.01, APO12.02, APO12.03, APO12.04
A20: 1.4.4 | B20: ID | C20: Identify | D20: RA | E20: Risk Assessment (ID.RA): The organization understands the cybersecurity risk to organizational operations (including mission, functions, image, or reputation), organizational assets, and individuals. | F20: ID.RA-4 | G20: Potential business impacts and likelihoods are identified | I20: Security Controls | K20: Risks assessments have been limited in scope and performed irregularly. There is not a risk management process to assess these risks for likelihood/impact. | L20: 1 | M20: High | N20: CIS CSC 4 | P20: RA-2, RA-3, SA-14, PM-9, PM-11 | Q20: 45 C.F.R. §§ 164.308(a)(1)(i), 164.308(a)(1)(ii)(A), 164.308(a)(1)(ii)(B), 164.308(a)(6), 164.308(a)(7)(ii)(E), 164.308(a)(8), 164.316(a) | S20: DSS04.02
A21: 1.4.5 | B21: ID | C21: Identify | D21: RA | E21: Risk Assessment (ID.RA): The organization understands the cybersecurity risk to organizational operations (including mission, functions, image, or reputation), organizational assets, and individuals. | F21: ID.RA-5 | G21: Threats, vulnerabilities, likelihoods, and impacts are used to determine risk | I21: Security Controls | K21: Risks assessments have been limited in scope and performed irregularly. There is no intentional risk management facility to assess risk. | L21: 1 | M21: Medium | N21: CIS CSC 4 | O21: A.12.6.1 | P21: RA-2, RA-3, PM-16 | Q21: 45 C.F.R. §§ 164.308(a)(1)(ii)(A), 164.308(a)(1)(ii)(B), 164.308(a)(1)(ii)(D), 164.308(a)(7)(ii)(D), 164.308(a)(7)(ii)(E), 164.316(a) | S21: APO12.02
A22: 1.4.6 | B22: ID | C22: Identify | D22: RA | E22: Risk Assessment (ID.RA): The organization understands the cybersecurity risk to organizational operations (including mission, functions, image, or reputation), organizational assets, and individuals. | F22: ID.RA-6 | G22: Risk responses are identified and prioritized | I22: Security Controls | K22: There is not documentation regarding risk management. | L22: 1 | M22: High | N22: CIS CSC 4 | P22: PM-4, PM-9 | Q22: 45 C.F.R. §§ 164.308(a)(1)(ii)(B), 164.314(a)(2)(i)(C), 164.314(b)(2)(iv) | S22: APO12.05, APO13.02
A23: 1.5.1 | B23: ID | C23: Identify | D23: RM | E23: Risk Management Strategy (ID.RM): The organization’s priorities, constraints, risk tolerances, and assumptions are established and used to support operational risk decisions. | F23: ID.RM-1 | G23: Risk management processes are established, managed, and agreed to by organizational stakeholders | H23: Risk Management | I23: GRC | K23: There is no risk management process defined. | L23: 1 | M23: High | N23: CIS CSC 4 | P23: PM-9 | Q23: 45 C.F.R. § 164.308(a)(1)(ii)(B) | S23: APO12.04, APO12.05, APO13.02, BAI02.03, BAI04.02
A24: 1.5.2 | B24: ID | C24: Identify | D24: RM | E24: Risk Management Strategy (ID.RM): The organization’s priorities, constraints, risk tolerances, and assumptions are established and used to support operational risk decisions. | F24: ID.RM-2 | G24: Organizational risk tolerance is determined and clearly expressed | H24: Risk Management | I24: GRC | K24: There is no risk tolerance determined or expressed in policy or via informal understanding. | L24: 1 | M24: Medium | P24: PM-9 | Q24: 45 C.F.R. § 164.308(a)(1)(ii)(B) | S24: APO12.06
A25: 1.5.3 | B25: ID | C25: Identify | D25: RM | E25: Risk Management Strategy (ID.RM): The organization’s priorities, constraints, risk tolerances, and assumptions are established and used to support operational risk decisions. | F25: ID.RM-3 | G25: The organization’s determination of risk tolerance is informed by its role in critical infrastructure and sector specific risk analysis | H25: Risk Management | I25: GRC | K25: There is no risk tolerance determined or expressed in policy or via informal understanding. | L25: 1 | M25: Medium | P25: SA-14, PM-8, PM-9, PM-11 | Q25: 45 C.F.R. §§ 164.308(a)(1)(ii)(B), 164.308(a)(6)(ii), 164.308(a)(7)(i), 164.308(a)(7)(ii)(C),164.308(a)(7)(ii)(E), 164.310(a)(2)(i)
A26: 1.6.1 | B26: ID | C26: Identify | D26: SC | E26: Supply Chain Risk Management (ID.SC): The organization’s priorities, constraints, risk tolerances, and assumptions are established and used to support risk decisions associated with managing supply chain risk. The organization has established and implemented the processes to identify, assess and manage supply chain risks. | F26: ID.SC-1 | G26: Cyber supply chain risk management processes are identified, established, assessed, managed, and agreed to by organizational stakeholders | H26: Vendor Risk Management | I26: GRC | K26: Processes are informal at best. There is evidence that Implementation Team does consider risk of major vendors during acquisition process. | L26: 1 | M26: High | N26: CIS CSC 4 | O26: A.9.2.1, A.9.2.2, A.9.2.4, A.9.3.1, A.9.4.2, A.9.4.3 | P26: SA-9, SA-12, PM-9 | S26: DSS05.04, DSS06.03
A27: 1.6.2 | B27: ID | C27: Identify | D27: SC | E27: Supply Chain Risk Management (ID.SC): The organization’s priorities, constraints, risk tolerances, and assumptions are established and used to support risk decisions associated with managing supply chain risk. The organization has established and implemented the processes to identify, assess and manage supply chain risks. | F27: ID.SC-2 | G27: Suppliers and third party partners of information systems, components, and services are identified, prioritized, and assessed using a cyber supply chain risk assessment process | H27: Vendor Risk Management | I27: GRC | K27: There is no sustained or document SCRM process, either in implementation or ongoing review. | L27: 1 | M27: Medium | O27: A.11.1.1, A.11.1.2, A.11.1.4, A.11.1.6, A.11.2.3 | P27: RA-2, RA-3, SA-12, SA-14, SA-15, PM-9 | S27: DSS01.04, DSS05.05
A28: 1.6.3 | B28: ID | C28: Identify | D28: SC | E28: Supply Chain Risk Management (ID.SC): The organization’s priorities, constraints, risk tolerances, and assumptions are established and used to support risk decisions associated with managing supply chain risk. The organization has established and implemented the processes to identify, assess and manage supply chain risks. | F28: ID.SC-3 | G28: Contracts with suppliers and third-party partners are used to implement appropriate measures designed to meet the objectives of an organization’s cybersecurity program and Cyber Supply Chain Risk Management Plan. | H28: Vendor Risk Assessments | I28: GRC | K28: The CLIENT does use BAAs as part of vendor contracts. These BAAs do reference HIPAA security expectations. There is little evidence of contractual review as it relates to the CLIENTS cybersecurity program or controls. | L28: 2 | M28: Medium | O28: A.6.2.2, A.13.1.1, A.13.2.1 | P28: SA-9, SA-11, SA-12, PM-9 | S28: APO13.01, DSS01.04, DSS05.03
A29: 1.6.4 | B29: ID | C29: Identify | D29: SC | E29: Supply Chain Risk Management (ID.SC): The organization’s priorities, constraints, risk tolerances, and assumptions are established and used to support risk decisions associated with managing supply chain risk. The organization has established and implemented the processes to identify, assess and manage supply chain risks. | F29: ID.SC-4 | G29: Suppliers and third-party partners are routinely assessed using audits, test results, or other forms of evaluations to confirm they are meeting their contractual obligations. | H29: Attestations of Compliance | I29: GRC | K29: No ongoing vendor review process is in place. | L29: 1 | M29: Medium | O29: A.6.1.2, A.9.1.2, A.9.2.3, A.9.4.1, A.9.4.4 | P29: AU-2, AU-6, AU-12, AU-16, PS-7, SA-9, SA-12
A30: 1.6.5 | B30: ID | C30: Identify | D30: SC | E30: Supply Chain Risk Management (ID.SC): The organization’s priorities, constraints, risk tolerances, and assumptions are established and used to support risk decisions associated with managing supply chain risk. The organization has established and implemented the processes to identify, assess and manage supply chain risks. | F30: ID.SC-5 | G30: Response and recovery planning and testing are conducted with suppliers and third-party providers | I30: Data | K30: Response/Recovery Planning is part of the expectations with the CLIENT'S IT provider. However, a test has not been performed and expecations are not formalized via contracts. | L30: 2 | M30: Low | N30: CIS CSC 19, 20 | O30: A.13.1.1, A.13.1.3, A.13.2.1 | P30: CP-2, CP-4, IR-3, IR-4, IR-6, IR-8, IR-9
A31: 2.1.1 | B31: PR | C31: Protect | D31: AC | E31: Identity Management, Authentication and Access Control (PR.AC): Access to physical and logical assets and associated facilities is limited to authorized users, processes, and devices, and is managed consistent with the assessed risk of unauthorized access to authorized activities and transactions. | F31: PR.AC-1 | G31: Identities and credentials are issued, managed, verified, revoked, and audited for authorized devices, users and processes | I31: Infrastructure | K31: Strong implementation of unique users in both AD and EHR. Role based permissions are established based on Job Role. User Reviews are not defined or performed. | L31: 2 | M31: High | N31: CIS CSC 1, 5, 15, 16 | O31: A.7.2.2 | P31: AC-1, AC-2, IA-1, IA-2, IA-3, IA-4, IA-5, IA-6, IA-7, IA-8, IA-9, IA-10, IA-11 | Q31: 45 C.F.R. §§ 164.308(a)(3)(ii)(B), 164.308(a)(3)(ii)(C), 164.308(a)(4)(i), 164.308(a)(4)(ii)(B), 164.308(a)(4)(ii)(C ), 164.312(a)(2)(i), 164.312(a)(2)(ii),164.312(a)(2)(iii), 164.312(d) | S31: APO07.03, BAI05.07
A32: 2.1.2 | B32: PR | C32: Protect | D32: AC | E32: Identity Management, Authentication and Access Control (PR.AC): Access to physical and logical assets and associated facilities is limited to authorized users, processes, and devices, and is managed consistent with the assessed risk of unauthorized access to authorized activities and transactions. | F32: PR.AC-2 | G32: Physical access to assets is managed and protected | H32: Network closets, Data Centers, Security Guards | I32: Infrastructure | K32: Sensitive equipment is physically secured behind locked doors and enclosures. There is not an audit process to ensure access controls are maintained. | L32: 2 | M32: Medium | O32: A.6.1.1, A.7.2.2 | P32: PE-2, PE-3, PE-4, PE-5, PE-6, PE-8 | Q32: 45 C.F.R. §§ 164.308(a)(1)(ii)(B), 164.308(a)(7)(i), 164.308(a)(7)(ii)(A), 164.310(a)(1), 164.310(a)(2)(i), 164.310(a)(2)(ii), 164.310(a)(2)(iii), 164.310(b), 164.310(c), 164.310(d)(1), 164.310(d)(2)(iii) | S32: APO07.02, DSS06.03
A33: 2.1.3 | B33: PR | C33: Protect | D33: AC | E33: Identity Management, Authentication and Access Control (PR.AC): Access to physical and logical assets and associated facilities is limited to authorized users, processes, and devices, and is managed consistent with the assessed risk of unauthorized access to authorized activities and transactions. | F33: PR.AC-3 | G33: Remote access is managed | I33: Infrastructure | K33: Remote Access is managed via Group Membership and requires documented approval (ticket). No policy or audit protocol is present. | L33: 2 | M33: High | N33: CIS CSC 12 | O33: A.6.1.1, A.7.2.2 | P33: AC-1, AC-17, AC-19, AC-20, SC-15 | Q33: 45 C.F.R. §§ 164.308(a)(4)(i), 164.308(b)(1), 164.308(b)(3), 164.310(b), 164.312(e)(1), 164.312(e)(2)(ii) | S33: APO07.03, APO10.04, APO10.05
A34: 2.1.4 | B34: PR | C34: Protect | D34: AC | E34: Identity Management, Authentication and Access Control (PR.AC): Access to physical and logical assets and associated facilities is limited to authorized users, processes, and devices, and is managed consistent with the assessed risk of unauthorized access to authorized activities and transactions. | F34: PR.AC-4 | G34: Access permissions and authorizations are managed, incorporating the principles of least privilege and separation of duties | I34: Infrastructure | K34: RBAC is implemented via AD. Users do not have local administrator permissions. | L34: 2 | M34: Low | N34: CIS CSC 3, 5, 12, 14, 15, 16, 18 | O34: A.6.1.1, A.7.2.2, | P34: AC-1, AC-2, AC-3, AC-5, AC-6, AC-14, AC-16, AC-24 | Q34: 45 C.F.R. §§ 164.308(a)(3), 164.308(a)(4), 164.310(a)(2)(iii), 164.310(b), 164.312(a)(1), 164.312(a)(2)(i), 164.312(a)(2)(ii) | S34: APO07.03
A35: 2.1.5 | B35: PR | C35: Protect | D35: AC | E35: Identity Management, Authentication and Access Control (PR.AC): Access to physical and logical assets and associated facilities is limited to authorized users, processes, and devices, and is managed consistent with the assessed risk of unauthorized access to authorized activities and transactions. | F35: PR.AC-5 | G35: Network integrity is protected (e.g., network segregation, network segmentation) | H35: Segmentation, Guest Wi-Fi | I35: Infrastructure | K35: Network is segmented via Firewalls, VLANs, and L3 ACLs. The Data VLAN is not segmented by Servers, Telemetry, Facility. There is not policy or procedure to set expectations. | L35: 2 | M35: Low | N35: CIS CSC 9, 14, 15, 18 | O35: A.6.1.1, A.7.2.2, | P35: AC-4, AC-10, SC-7 | Q35: 45 C.F.R. §§ 164.308(a)(4)(ii)(B), 164.310(a)(1), 164.310(b), 164.312(a)(1), 164.312(b), 164.312(c), 164.312(e) | S35: APO07.03
A36: 2.1.6 | B36: PR | C36: Protect | D36: AC | E36: Identity Management, Authentication and Access Control (PR.AC): Access to physical and logical assets and associated facilities is limited to authorized users, processes, and devices, and is managed consistent with the assessed risk of unauthorized access to authorized activities and transactions. | F36: PR.AC-6 | G36: Identities are proofed and bound to credentials and asserted in interactions | H36: Unique User Accounts | I36: Infrastructure | K36: Unique user accounts are created in AD and EHR. No policy or audit protocol is present. | L36: 2 | M36: Low | N36: CIS CSC, 16 | O36: A.8.2.3 | P36: AC-1, AC-2, AC-3, AC-16, AC-19, AC-24, IA-1, IA-2, IA-4, IA-5, IA-8, PE-2, PS-3 | S36: APO01.06, BAI02.01, BAI06.01, DSS06.06
A37: 2.1.7 | B37: PR | C37: Protect | D37: AC | E37: Identity Management, Authentication and Access Control (PR.AC): Access to physical and logical assets and associated facilities is limited to authorized users, processes, and devices, and is managed consistent with the assessed risk of unauthorized access to authorized activities and transactions. | F37: PR.AC-7 | G37: Users, devices, and other assets are authenticated (e.g., single-factor, multi-factor) commensurate with the risk of the transaction (e.g., individuals’ security and privacy risks and other organizational risks) | H37: Local accounts (Sys, Net) MFA (VPN, Cloud) | I37: Infrastructure | K37: MFA is implemented in cloud, mail, vpn. Built in domain admin is disabled. Service accounts are not appropriately labeled / secured. | L37: 2 | M37: Medium | N37: CIS CSC 1, 12, 15, 16 | O37: A.8.2.3, A.13.1.1, A.13.2.1, A.13.2.3, A.14.1.2, A.14.1.3 | P37: AC-7, AC-8, AC-9, AC-11, AC-12, AC-14, IA-1, IA-2, IA-3, IA-4, IA-5, IA-8, IA-9, IA-10, IA-11 | S37: APO01.06, DSS06.06
A38: 2.2.1 | B38: PR | C38: Protect | D38: AT | E38: The organization’s personnel and partners are provided cybersecurity awareness education and are trained to perform their cybersecurity-related duties and responsibilities consistent with related policies, procedures, and agreements | F38: PR.AT-1 | G38: All users are informed and trained | H38: Security Awareness | I38: Security Controls | K38: There is a brief security training as part of onboarding and informal topics are covered in meetings on an ad-hoc basis. There is no formal security training on an ongoing basis. Including education regarding IS policy. | L38: 2 | M38: High | N38: CIS CSC 17, 18 | O38: A.8.2.3, A.8.3.1, A.8.3.2, A.8.3.3, A.11.2.7 | P38: AT-2, PM-13 | Q38: 45 C.F.R. § 164.308(a)(5) | S38: BAI09.03
A39: 2.2.2 | B39: PR | C39: Protect | D39: AT | E39: The organization’s personnel and partners are provided cybersecurity awareness education and are trained to perform their cybersecurity-related duties and responsibilities consistent with related policies, procedures, and agreements | F39: PR.AT-2 | G39: Privileged users understand their roles and responsibilities | H39: Access Controls, Admin Account Use for Daily Tasks | I39: Infrastructure | K39: Admin accounts are not used for daily tasks. Good understanding of the appropriate usage of user accounts.No policy or audit protocol is present. | L39: 2 | M39: Medium | N39: CIS CSC 5, 17, 18 | O39: A.12.3.1 | P39: AT-3, PM-13 | Q39: 5 C.F.R. §§ 164.308(a)(2), 164.308(a)(3)(i), 164.308(a)(5)(i), 164.308(a)(5)(ii)(A), 164.308(a)(5)(ii)(B), 164.308(a)(5)(ii)(C), 164.308(a)(5)(ii)(D) | S39: APO13.01
A40: 2.2.3 | B40: PR | C40: Protect | D40: AT | E40: The organization’s personnel and partners are provided cybersecurity awareness education and are trained to perform their cybersecurity-related duties and responsibilities consistent with related policies, procedures, and agreements | F40: PR.AT-3 | G40: Third-party stakeholders (e.g., suppliers, customers, partners) understand their roles and responsibilities | H40: Vendor Management | I40: Infrastructure | K40: BAAs outline third-party responsibilities. | L40: 2 | M40: Low | N40: CIS CSC 17 | O40: A.6.1.2, A.7.1.1, A.7.1.2, A.7.3.1, A.8.2.2, A.8.2.3, A.9.1.1, A.9.1.2, A.9.2.3, A.9.4.1, A.9.4.4, A.9.4.5, A.13.1.3, A.13.2.1, A.13.2.3, A.13.2.4, A.14.1.2, A.14.1.3 | P40: PS-7, SA-9, SA-16 | Q40: 45 C.F.R. §§ 164.308(b), 164.314(a)(1), 164.314(a)(2)(i), 164.314(a)(2)(ii) | S40: APO01.06
...

Sheet Scoring
A1: Function | B1: Function Tier Score | C1: Category | D1: Category Tier Score | E1: Subcategory | F1: Subcategory Tier Score
A2: Identify | B2: =AVERAGEIF(E2:E109,"*ID.*",F2:F109) -> 1.3448276 | C2: Asset Management (ID.AM) | D2: =AVERAGEIF(E2:E109,"*ID.AM*",F2:F109) -> 1.3333333 | E2: ID.AM-1 | F2: =Tbl_Assess[[#This Row],[Assessed Tier]] -> 1
E3: ID.AM-2 | F3: =Tbl_Assess[[#This Row],[Assessed Tier]] -> 2
E4: ID.AM-3 | F4: =Tbl_Assess[[#This Row],[Assessed Tier]] -> 1
E5: ID.AM-4 | F5: =Tbl_Assess[[#This Row],[Assessed Tier]] -> 2
E6: ID.AM-5 | F6: =Tbl_Assess[[#This Row],[Assessed Tier]] -> 1
E7: ID.AM-6 | F7: =Tbl_Assess[[#This Row],[Assessed Tier]] -> 1
C8: Business Environment (ID.BE) | D8: =AVERAGEIF(E2:E109,"*ID.BE*",F2:F109) -> 1.6 | E8: ID.BE-1 | F8: =Tbl_Assess[[#This Row],[Assessed Tier]] -> 2
E9: ID.BE-2 | F9: =Tbl_Assess[[#This Row],[Assessed Tier]] -> 2
E10: ID.BE-3 | F10: =Tbl_Assess[[#This Row],[Assessed Tier]] -> 2
E11: ID.BE-4 | F11: =Tbl_Assess[[#This Row],[Assessed Tier]] -> 1
E12: ID.BE-5 | F12: =Tbl_Assess[[#This Row],[Assessed Tier]] -> 1
C13: Governance (ID.GV) | D13: =AVERAGEIF(E2:E109,"*ID.GV*",F2:F109) -> 1.5 | E13: ID.GV-1 | F13: =Tbl_Assess[[#This Row],[Assessed Tier]] -> 1
E14: ID.GV-2 | F14: =Tbl_Assess[[#This Row],[Assessed Tier]] -> 2
E15: ID.GV-3 | F15: =Tbl_Assess[[#This Row],[Assessed Tier]] -> 2
E16: ID.GV-4 | F16: =Tbl_Assess[[#This Row],[Assessed Tier]] -> 1
C17: Risk Assessment (ID.RA) | D17: =AVERAGEIF(E2:E109,"*ID.RA*",F2:F109) -> 1.1666667 | E17: ID.RA-1 | F17: =Tbl_Assess[[#This Row],[Assessed Tier]] -> 2
E18: ID.RA-2 | F18: =Tbl_Assess[[#This Row],[Assessed Tier]] -> 1
E19: ID.RA-3 | F19: =Tbl_Assess[[#This Row],[Assessed Tier]] -> 1
E20: ID.RA-4 | F20: =Tbl_Assess[[#This Row],[Assessed Tier]] -> 1
E21: ID.RA-5 | F21: =Tbl_Assess[[#This Row],[Assessed Tier]] -> 1
E22: ID.RA-6 | F22: =Tbl_Assess[[#This Row],[Assessed Tier]] -> 1
C23: Risk Management Strategy (ID.RM) | D23: =AVERAGEIF(E2:E109,"*ID.RM*",F2:F109) -> 1 | E23: ID.RM-1 | F23: =Tbl_Assess[[#This Row],[Assessed Tier]] -> 1
E24: ID.RM-2 | F24: =Tbl_Assess[[#This Row],[Assessed Tier]] -> 1
E25: ID.RM-3 | F25: =Tbl_Assess[[#This Row],[Assessed Tier]] -> 1
C26: Supply Chain Risk Management (ID.SC) | D26: =AVERAGEIF(E2:E109,"*ID.SC*",F2:F109) -> 1.4 | E26: ID.SC-1 | F26: =Tbl_Assess[[#This Row],[Assessed Tier]] -> 1
E27: ID.SC-2 | F27: =Tbl_Assess[[#This Row],[Assessed Tier]] -> 1
E28: ID.SC-3 | F28: =Tbl_Assess[[#This Row],[Assessed Tier]] -> 2
E29: ID.SC-4 | F29: =Tbl_Assess[[#This Row],[Assessed Tier]] -> 1
E30: ID.SC-5 | F30: =Tbl_Assess[[#This Row],[Assessed Tier]] -> 2
A31: Protect | B31: =AVERAGEIF(E2:E109,"*PR.*",F2:F109) -> 1.8717949 | C31: Identity Management and Access Control (PR.AC) | D31: =AVERAGEIF(E2:E109,"*PR.AC*",F2:F109) -> 2 | E31: PR.AC-1 | F31: =Tbl_Assess[[#This Row],[Assessed Tier]] -> 2
E32: PR.AC-2 | F32: =Tbl_Assess[[#This Row],[Assessed Tier]] -> 2
E33: PR.AC-3 | F33: =Tbl_Assess[[#This Row],[Assessed Tier]] -> 2
E34: PR.AC-4 | F34: =Tbl_Assess[[#This Row],[Assessed Tier]] -> 2
E35: PR.AC-5 | F35: =Tbl_Assess[[#This Row],[Assessed Tier]] -> 2
E36: PR.AC-6 | F36: =Tbl_Assess[[#This Row],[Assessed Tier]] -> 2
E37: PR.AC-7 | F37: =Tbl_Assess[[#This Row],[Assessed Tier]] -> 2
C38: Awareness and Training (PR.AT) | D38: =AVERAGEIF(E2:E109,"*PR.AT*",F2:F109) -> 2 | E38: PR.AT-1 | F38: =Tbl_Assess[[#This Row],[Assessed Tier]] -> 2
E39: PR.AT-2 | F39: =Tbl_Assess[[#This Row],[Assessed Tier]] -> 2
E40: PR.AT-3 | F40: =Tbl_Assess[[#This Row],[Assessed Tier]] -> 2
...

Sheet Summary
A1: Summary Tables
A2: Function | C2: Current Tier | D2: Target Tier
B3: Identify | C3: =Scoring!B2 -> 1.3448276 | D3: =TargetMaturityTier -> 3
B4: Protect | C4: =Scoring!B31 -> 1.8717949 | D4: =TargetMaturityTier -> 3
B5: Detect | C5: =Scoring!B70 -> 1.5 | D5: =TargetMaturityTier -> 3
B6: Respond | C6: =Scoring!B88 -> 1.8125 | D6: =TargetMaturityTier -> 3
B7: Recover | C7: =Scoring!B104 -> 1.3333333 | D7: =TargetMaturityTier -> 3
A9: Function | B9: Category | C9: Current Tier | D9: Target Tier
A10: ID | B10: Asset Management (ID.AM) | C10: =Scoring!D2 -> 1.3333333 | D10: =TargetMaturityTier -> 3
A11: ID | B11: Business Environment (ID.BE) | C11: =Scoring!D8 -> 1.6 | D11: =TargetMaturityTier -> 3
A12: ID | B12: Governance (ID.GV) | C12: =Scoring!D13 -> 1.5 | D12: =TargetMaturityTier -> 3
A13: ID | B13: Risk Assessment (ID.RA) | C13: =Scoring!D17 -> 1.1666667 | D13: =TargetMaturityTier -> 3
A14: ID | B14: Risk Management Strategy (ID.RM) | C14: =Scoring!D23 -> 1 | D14: =TargetMaturityTier -> 3
A15: ID | B15: Supply Chain Risk Management (ID.SC) | C15: =Scoring!D26 -> 1.4 | D15: =TargetMaturityTier -> 3
A16: PR | B16: Identity Management and Access Control (PR.AC) | C16: =Scoring!D31 -> 2 | D16: =TargetMaturityTier -> 3
A17: PR | B17: Awareness and Training (PR.AT) | C17: =Scoring!D38 -> 2 | D17: =TargetMaturityTier -> 3
A18: PR | B18: Data Security (PR.DS) | C18: =Scoring!D43 -> 2 | D18: =TargetMaturityTier -> 3
A19: PR | B19: Information Protection (PR.IP) | C19: =Scoring!D51 -> 1.75 | D19: =TargetMaturityTier -> 3
A20: PR | B20: Maintenance (PR.MA) | C20: =Scoring!D63 -> 2 | D20: =TargetMaturityTier -> 3
A21: PR | B21: Protective Technology (PR.PT) | C21: =Scoring!D65 -> 1.6 | D21: =TargetMaturityTier -> 3
A22: DE | B22: Anomalies and Events (DE.AE) | C22: =Scoring!D70 -> 1.6 | D22: =TargetMaturityTier -> 3
A23: DE | B23: Security Continuous Monitoring (DE.CM) | C23: =Scoring!D75 -> 1.5 | D23: =TargetMaturityTier -> 3
A24: DE | B24: Detection Processes (DE.DP) | C24: =Scoring!D83 -> 1.4 | D24: =TargetMaturityTier -> 3
A25: RS | B25: Response Planning (RS.RP) | C25: =Scoring!D88 -> 2 | D25: =TargetMaturityTier -> 3
A26: RS | B26: Communications (RS.CO) | C26: =Scoring!D89 -> 2 | D26: =TargetMaturityTier -> 3
A27: RS | B27: Analysis (RS.AN) | C27: =Scoring!D94 -> 1.8 | D27: =TargetMaturityTier -> 3
A28: RS | B28: Mitigation (RS.MI) | C28: =Scoring!D99 -> 1.6666667 | D28: =TargetMaturityTier -> 3
A29: RS | B29: Improvements (RS.IM) | C29: =Scoring!D102 -> 1.5 | D29: =TargetMaturityTier -> 3
A30: RC | B30: Recovery Planning (RC.RP) | C30: =Scoring!D104 -> 2 | D30: =TargetMaturityTier -> 3
A31: RC | B31: Improvements (RC.IM) | C31: =Scoring!D105 -> 1 | D31: =TargetMaturityTier -> 3
A32: RC | B32: Communications (RC.CO) | C32: =Scoring!D107 -> 1.3333333 | D32: =TargetMaturityTier -> 3

Sheet Charts

Sheet CSF Overview
A1: Overview | B1: The NIST Cybersecurity Framework is voluntary guidance, based on existing standards, guidelines, and practices for organizations to better manage and reduce cybersecurity risk. In addition to helping organizations manage and reduce risks, it was designed to foster risk and cybersecurity management communications amongst both internal and external organizational stakeholders.
A3: Core | B3: The Framework Core provides a set of desired cybersecurity activities and outcomes using common language that is easy to understand. The Core guides organizations in managing and reducing their cybersecurity risks in a way that complements an organization’s existing cybersecurity and risk management processes.
A5: Tiers | B5: The Framework Implementation Tiers assist organizations by providing context on how an organization views cybersecurity risk management. The Tiers guide organizations to consider the appropriate level of rigor for their cybersecurity program and are often used as a communication tool to discuss risk appetite, mission priority, and budget.
A6: Tier 1: Partial | B6: Risk Management Process – Organizational cybersecurity risk management practices are not formalized, and risk is managed in an ad hoc and sometimes reactive manner. Prioritization of cybersecurity activities may not be directly informed by organizational risk objectives, the threat environment, or business/mission requirements. Integrated Risk Management Program – There is limited awareness of cybersecurity risk at the organizational level. The organization implements cybersecurity risk management on an irregular, case-by-case basis due to varied experience or information gained from outside sources. The organization may not have processes that enable cybersecurity information to be shared within the organization. External Participation – The organization does not understand its role in the larger ecosystem with respect to either its dependencies or dependents. The organization does not collaborate with or receive information (e.g., threat intelligence, best practices, technologies) from other entities (e.g., buyers, suppliers, dependencies, dependents, ISAOs, researchers, governments), nor does it share information. The organization is generally unaware of the cyber supply chain risks of the products and services it provides and that it uses.
A7: Tier 2: Risk Informed | B7: Risk Management Process – Risk management practices are approved by management but may not be established as organizational-wide policy. Prioritization of cybersecurity activities and protection needs is directly informed by organizational risk objectives, the threat environment, or business/mission requirements. Integrated Risk Management Program – There is an awareness of cybersecurity risk at the organizational level, but an organization-wide approach to managing cybersecurity risk has not been established. Cybersecurity information is shared within the organization on an informal basis. Consideration of cybersecurity in organizational objectives and programs may occur at some but not all levels of the organization. Cyber risk assessment of organizational and external assets occurs, but is not typically repeatable or reoccurring. External Participation – Generally, the organization understands its role in the larger ecosystem with respect to either its own dependencies or dependents, but not both. The organization collaborates with and receives some information from other entities and generates some of its own information, but may not share information with others. Additionally, the organization is aware of the cyber supply chain risks associated with the products and services it provides and uses, but does not act consistently or formally upon those risks.
A8: Tier 3: Repeatable | B8: Risk Management Process – The organization’s risk management practices are formally approved and expressed as policy. Organizational cybersecurity practices are regularly updated based on the application of risk management processes to changes in business/mission requirements and a changing threat and technology landscape. Integrated Risk Management Program – There is an organization-wide approach to manage cybersecurity risk. Risk-informed policies, processes, and procedures are defined, implemented as intended, and reviewed. Consistent methods are in place to respond effectively to changes in risk. Personnel possess the knowledge and skills to perform their appointed roles and responsibilities. The organization consistently and accurately monitors cybersecurity risk of organizational assets. Senior cybersecurity and non-cybersecurity executives communicate regularly regarding cybersecurity risk. Senior executives ensure consideration of cybersecurity through all lines of operation in the organization. External Participation – The organization understands its role, dependencies, and dependents in the larger ecosystem and may contribute to the community’s broader understanding of risks. It collaborates with and receives information from other entities regularly that complements internally generated information, and shares information with other entities. The organization is aware of the cyber supply chain risks associated with the products and services it provides and that it uses. Additionally, it usually acts formally upon those risks, including mechanisms such as written agreements to communicate baseline requirements, governance structures (e.g., risk councils), and policy implementation and monitoring.
A9: Tier 4: Adaptable | B9: Risk Management Process – The organization adapts its cybersecurity practices based on previous and current cybersecurity activities, including lessons learned and predictive indicators. Through a process of continuous improvement incorporating advanced cybersecurity technologies and practices, the organization actively adapts to a changing threat and technology landscape and responds in a timely and effective manner to evolving, sophisticated threats. Integrated Risk Management Program – There is an organization-wide approach to managing cybersecurity risk that uses risk-informed policies, processes, and procedures to address potential cybersecurity events. The relationship between cybersecurity risk and organizational objectives is clearly understood and considered when making decisions. Senior executives monitor cybersecurity risk in the same context as financial risk and other organizational risks. The organizational budget is based on an understanding of the current and predicted risk environment and risk tolerance. Business units implement executive vision and analyze system-level risks in the context of the organizational risk tolerances. Cybersecurity risk management is part of the organizational culture and evolves from an awareness of previous activities and continuous awareness of activities on their systems and networks. The organization can quickly and efficiently account for changes to business/mission objectives in how risk is approached and communicated. External Participation – The organization understands its role, dependencies, and dependents in the larger ecosystem and contributes to the community’s broader understanding of risks. It receives, generates, and reviews prioritized information that informs continuous analysis of its risks as the threat and technology landscapes evolve. The organization shares that information internally and externally with other collaborators. The organization uses real-time or near real-time information to understand and consistently act upon cyber supply chain risks associated with the products and services it provides and that it uses. Additionally, it communicates proactively, using formal (e.g. agreements) and informal mechanisms to develop and maintain strong supply chain relationships.
B11: The NIST CSF is available free of charge from NIST.
B12: https://www.nist.gov/cyberframework/framework

Sheet KEY
A2: Tier | B2: Desc. | D2: Priority
A3: 1 | B3: Partial | D3: Critical
A4: 2 | B4: Risk Informed (Thought about it) | D4: High
A5: 3 | B5: Repeatable (Considered and Codified) | D5: Medium
A6: 4 | B6: Adaptable | D6: Low
A7: N/A
