Workbook

Sheet Main
A306: DR | B306: =CONCATENATE('Data resiliency'!$H$56,"/",'Data resiliency'!$A$56," Assessed") -> 0/13 Assessed
A307: AC | B307: =CONCATENATE('Access Control'!$H$57,"/",'Access Control'!$A$57," Assessed") -> 0/41 Assessed
A308: DL | B308: =CONCATENATE('Data Leakage'!$H$96,"/",'Data Leakage'!$A$96," Assessed") -> 0/82 Assessed
A309: SC | B309: =CONCATENATE('Security & Compliance'!$H$134,"/",'Security & Compliance'!$A$134," Assessed") -> 0/80 Assessed
A310: IR | B310: =CONCATENATE('Incident Response'!$H$101,"/",'Incident Response'!$A$101," Assessed") -> 0/63 Assessed

Sheet Data resiliency
A1: Category | B1: Product | C1: Feature | D1: Description | E1: Portal | F1: PS Configure | G1: PS Get | H1: Assessed
A2: Resilience DR | B2: Office 365 | C2: Data Resilience DR | D2: To help organizations meet complex incidents introduced by logical corruption or illicit modifications of stored information Office 365 has several features that can help salvage information.
A3: Resilience DR | B3: Exchange | C3: Exchange | D3: In Exchange Online both users and administrators can recover data. There may be situations where recoverable data is not available to end users where the recovery need to be conducted by customer administrators. Customer service administrators may need to make recoveries due to modifications of existing calendar items as an example.
A4: Resilience DR | B4: Exchange | C4: Single Item Recovery | D4: Customer administrators can search for and recover deleted email messages in a user's mailbox. This includes items that are permanently deleted (purged) by a person (by using the Recover Deleted Items feature in Outlook or Outlook Web App), or items deleted or modified by an automated process.
A5: Resilience DR | B5: Exchange | C5: Recoverable Items | D5: The Recoverable Items folder contains a number of subfolders the Deletions subfolder contains the items deleted from the Deleted Items folder. (In Outlook, a user can soft delete an item by pressing Shift+Delete.) This subfolder is exposed to users through the Recover Deleted Items feature in Outlook and Outlook Web App.
A6: Resilience DR | B6: Exchange | C6: Restore Deleted Mailboxes | D6: A soft-deleted mailbox is retained in the source database until the deleted mailbox retention period expires or until the Remove-StoreMailbox cmdlet is used to purge the soft-deleted mailbox.
A7: Resilience DR | B7: SharePoint | C7: SharePoint | D7: SharePoint has a rich set of capabilities to restore information that has been modified by mistake or maliciously.
A8: Resilience DR | B8: SharePoint | C8: SharePoint Recycle Bin | D8: SharePoint Online sites offer end-user and site collection administrator views to the Recycle Bin. The end user can see any items he or she deleted, a site collection administrator, can see all items deleted by any user within the site collection
A9: Resilience DR | B9: SharePoint | C9: SharePoint Versioning | D9: Anyone with permission to manage lists can turn versioning on or off for a library. Versioning is available for list items in all default list types—including calendars, issue tracking lists, and custom lists. It is also available for all file types that can be stored in libraries, including Web Part pages. Versioning is turned on by default when you create new OneDrive for Business libraries in Office 365, and it will automatically save the last ten versions of a document.
A10: Resilience DR | B10: SharePoint | C10: OneDrive for Business Deletion | D10: When a OneDrive for Business site collection is scheduled for deletion, the default action is to transfer ownership of the site to the manager. For this to occur, the user profile Manager property must be set for the original owner of the OneDrive for Business site.
A11: Discover DP | B11: Office 365 | C11: Discover (DP) | D11: With immense costs for legal review and ever growing amounts of data, organizations are struggling to find the right set of data. With legal review costs ranging from $10,000 per $40,000 per gigabyte there is a strong incentive to minimize the data organizations send to review and production. Office 365 has a rich set of tools that organizations can use to minimize the amount of data that need to be produced for legal review.
A12: Discover DP | B12: Office 365 | C12: Search from a Single Unified Portal | D12: The eDiscovery Center is used to manage new and existing eDiscovery cases and close eDiscovery cases that are no longer needed. This provide a systemic approach to eDiscovery across Office 365.
A13: Preserve DP | B13: Exchange | C13: PST Ingestion | D13: Organizations where users keep a lot of information in their PST files may run a risk of keeping information out of policy which can be damaging in a court case if not produced correctly. Exchange Online allow for customers to upload users PST files and ingest them in to Exchange Online. | E13: Office 365 Portal Import
A14: Preserve DP | B14: SharePoint | C14: Place Content on in-place Hold | D14: Query based hold in Office 365 allow organizations to not only hold information from SharePoint but also for Skype for business, Exchange and OneDrive for Business.
A56: =COUNTA(A2:A44) -> 13 | H56: =COUNTA(H2:H44) -> 0

Sheet Access Control
A1: Category | B1: Product | C1: Feature | D1: Description | E1: Portal | F1: PS Configure | G1: PS Get | H1: Assessed
A2: Admin AC | B2: O365 | C2: Access Control Admin (AC) | D2: The Access Control Admin category covers the aspects of a trusted administration model that is different from the model used for users. If the accounts used for administration can't be monitored or trusted it breaches the security of the entire system.
A3: Admin AC | B3: O365 | C3: Separation of Duties | D3: Depending on the size of your organization, you may want to designate several admins who serve different functions. The admin has access to all features in the admin center, and can create or edit users, assign admin roles to others, reset user passwords, manage user licenses, and manage domains, among other things. Office 365 includes a security model that enables separation of administration based on roles. Certain admin roles Office 365 have a corresponding role in Exchange Online, SharePoint Online, and Skype for Business Online. | E3: Select the user and edit user roles
A4: Admin AC | B4: Exchange | C4: Separate Exchange Administrators | D4: Depending on the size of your organization, you may want to designate several admins who serve different functions. The admin has access to all features in the admin center, and can create or edit users, assign admin roles to others, reset user passwords, manage user licenses, and manage domains, among other things. Office 365 includes a security model that enables separation of administration based on roles. Certain admin roles Office 365 have a corresponding role in Exchange Online, SharePoint Online, and Skype for Business Online. Segment permissions to ensure that a single administrator doesn't have greater access than necessary. | E4: Select the user and edit user roles | F4: Set-MsolRoleMember | G4: Get-MsolRoleMember
A5: Admin AC | B5: SharePoint | C5: Separate SharePoint Administrators | D5: Depending on the size of your organization, you may want to designate several admins who serve different functions. The admin has access to all features in the admin center, and can create or edit users, assign admin roles to others, reset user passwords, manage user licenses, and manage domains, among other things. Office 365 includes a security model that enables separation of administration based on roles. Certain admin roles Office 365 have a corresponding role in Exchange Online, SharePoint Online, and Skype for Business Online. Segment permissions to ensure that a single administrator doesn't have greater access than necessary. | E5: Select the user and edit user roles | F5: Set-MsolRoleMember | G5: Get-MsolRoleMember
A6: Admin AC | B6: Skype4B | C6: Separate Skype for Business Administrators | D6: Depending on the size of your organization, you may want to designate several admins who serve different functions. The admin has access to all features in the admin center, and can create or edit users, assign admin roles to others, reset user passwords, manage user licenses, and manage domains, among other things. Office 365 includes a security model that enables separation of administration based on roles. Certain admin roles Office 365 have a corresponding role in Exchange Online, SharePoint Online, and Skype for Business Online. Segment permissions to ensure that a single administrator doesn't have greater access than necessary. | E6: Select the user and edit user roles | F6: Set-MsolRoleMember | G6: Get-MsolRoleMember
A7: Admin AC | B7: Exchange | C7: Exchange Online Privileged Accounts | D7: Perform regular reviews of all users and groups with high levels of permissions. You can search the administrator audit logs to discover who made changes to organization, server, and recipient configuration. This can be helpful when you're trying to track the cause of unexpected behavior, to identify a malicious administrator, to investigate data leaks, or to verify that compliance requirements are being met. | E7: Permissions / Admin Groups
A8: Admin AC | B8: Exchange | C8: Administrator role group changes | D8: Verify that high-privileged roles have not been assigned to any un-authorized users. You can search the administrator audit logs or the Activity logs to discover who made changes to organization, server, and recipient configuration. This can be helpful when you're trying to track the cause of unexpected behavior, to identify a malicious administrator, to investigate data leaks, or to verify that compliance requirements are being met. | E8: Role Group Report | F8: On by default in Office 365 | G8: Get-AdminAuditLogConfig | FL AdminAuditLogEnabled, Search-AdminAuditLog
A9: Admin AC | B9: SharePoint | C9: SharePoint Online Permissions | D9: If you are a SharePoint Online admin, you probably want to control who can make changes on your site. Ensure that the proper users have administrative privileges to appropriate content. Each site collection has its own set of permission levels. SharePoint comes with some default permission levels that you can use, such as Contribute and View Only. But if one of those doesn’t meet your needs, you can create a new permissions level. It’s a best practice that you don’t change the default permission levels. See also https://support.office.com/en-us/article/How-to-create-and-edit-Permission-Levels-53c86040-07fa-4ea7-bc55-34ee96b437fe#__best_practices_for. | F9: Set-SPOSiteGroup, Set-SPOUser | G9: Get-SPOSiteGroup, Get-SPOUser
A10: Admin AC | B10: SharePoint | C10: Review Modification of permissions | D10: Changes to user accounts and permissions should happen regularly to quickly respond to potentially malicious activities. Knowing who has done what with which information is critical for many business requirements, such as regulatory compliance and records management. You can use the audit feature in SharePoint Online to track which users have taken what actions on the sites, content types, lists, libraries, list items, and library files within your site collections. | F10: Set-SPOSiteGroup, Set-SPOUser | G10: Get-SPOSiteGroup, Get-SPOUser
A11: Admin AC | B11: O365 | C11: Customer Lockbox | D11: Microsoft engineers do not have standing access to any service operation. All access is obtained through a rigorous access control technology called Lockbox that enforces access control through multiple levels of approval within Microsoft, providing just-in-time access with limited and time-bound authorization. In addition, all access control activities in the service are logged and audited. Customers are part of the Lockbox approval process for instances involving access to customer content. The customer-facing side of the approval process is called Customer Lockbox. Use of the Customer Lockbox feature ensures that a Microsoft engineer does not get access to customer content without the customer’s explicit approval. Customer Lockbox gives customers explicit approval tools in the rare case when a Microsoft engineer needs access to customer content to resolve a customer-reported issue.
A12: Admin AC | B12: O365 | C12: Review Delegated Partner Administrators | D12: Ensure that partner organizations don't have standing access to the environment unless warranted. This will limit the potential attack surface.
A13: Authentication IA | B13: O365 | C13: Authentication (IA) | D13: The Authentication category covers the options and features available for authentication within Office 365. The list contains Microsoft technologies available both on-premises and in the cloud. Please see this information from the main Customer Security Considerations Pivot if you are using the Fed Ramp control listing.
A14: Authentication IA | B14: O365 | C14: Token Life time | D14: This feature allows you to create token lifetime policies. These policies define how long tokens issued by Azure AD are considered valid. This influences how often users must enter their credentials. These policies can be set as defaults that apply to all applications in a tenant and they can also be linked to applications or service principals. The policies are managed through Azure PowerShell.
A15: Authentication IA | B15: AzureAD | C15: Passwords | D15: Weak passwords trump strong security, so have a good process for passwords and don't re-use them for other systems. Once you've picked strong passwords, handle them appropriately. consider using something stronger than – and in addition to – passwords to identify yourself to the system. Windows, for instance, supports the use of smart cards, which significantly strengthens the account checking the system can perform. You may also want to consider biometric products such as fingerprint and retina scanners. “Two-factor authentication” of this sort incorporates not only something you know (your password) but something you own (a card) or even something you are (a person with your unique fingerprint or retina) – dramatically increasing authentication strength.
A16: Authentication IA | B16: AzureAD | C16: Azure AD Password | D16: Make it difficult to crack or guess user passwords. | E16: Password Settings Portal complex use PowerShell | F16: Set-MsolPasswordPolicy, Set-MsolUser | G16: Get-MsolPasswordPolicy, Get-MsolUser
A17: Authentication IA | B17: AzureAD | C17: Deploying Password Management and training users to use it | D17: To make password reset actions effective organizations can use various methods to ensure that every user in the organization can use self-service password reset effectively in case they forget their password to lessen the administrative burden.
A18: Authentication IA | B18: AzureAD | C18: Review self-service password reset alt phone and email changes | D18: Modification of the contact details may show proof of illicit behavior in the environment.
A19: Authentication IA | B19: AzureAD | C19: Machine generate application passwords | D19: Use machine-generated passwords for administrator accounts or high-privileged accounts to provide a degree of obstruction. Passwords that aren't tied to an individual should be placed in an audited vault and updated on a regular basis.
A20: Authentication IA | B20: AzureAD | C20: Password Age Meets Policy | D20: If the password age doesn't meet the policy reset the password to protect the environment.
A21: Authentication IA | B21: AzureAD | C21: Password Age Policy < 60 Days | D21: This determines how long users can keep a password before they have to change it. The aim is to force users to change their passwords periodically. Generally, you use a shorter period when security is important.
A22: Authentication IA | B22: AzureAD | C22: Store secrets in a Key Vault | D22: Any script or code that uses authenticators should store it in a Secrets Management System. The same is true for other secrets such as certificates. Azure Key Vault helps safeguard cryptographic keys and secrets used by cloud applications and services. By using Key Vault, you can encrypt keys and secrets (such as authentication keys, storage account keys, data encryption keys, .PFX files, and passwords) by using keys that are protected by hardware security modules (HSMs). For added assurance, you can import or generate keys in HSMs. Key Vault streamlines the key management process and enables you to maintain control of keys that access and encrypt your data. Developers can create keys for development and testing in minutes, and then seamlessly migrate them to production keys. Security administrators can grant (and revoke) permission to keys, as needed.
A23: Authentication IA | B23: AzureAD | C23: Multi-factor authentication Office 365 | D23: Multi-factor authentication (MFA) is a method of authentication that requires the use of more than one verification method and adds a second layer of security to user sign-ins and transactions. You can also use any other MFA solutions that are offered with your on-premises directory. For example, the works with Office 365 program identity providers might offer different MFA solutions that you can manage according to the identity provider's specifications. For more information, see http://go.microsoft.com/fwlink/p/?LinkId=510953. | E23: Multi Factor Portal | F23: https://msdn.microsoft.com/en-us/library/azure/dn394289.aspx | G23: Get-MsolUser
A24: Authentication IA | B24: AzureAD | C24: Tenant Admins MFA Enabled | D24: Multi-factor authentication (MFA) is a method of authentication that requires the use of more than one verification method and adds a second layer of security to user sign-ins and transactions. You can also use any other MFA solutions that are offered with your on-premises directory. For example, the works with Office 365 program identity providers might offer different MFA solutions that you can manage according to the identity provider's specifications. For more information, see http://go.microsoft.com/fwlink/p/?LinkId=510953.
A25: Authentication IA | B25: AzureAD | C25: Users MFA Enabled | D25: Multi-factor authentication (MFA) is a method of authentication that requires the use of more than one verification method and adds a second layer of security to user sign-ins and transactions. You can also use any other MFA solutions that are offered with your on-premises directory. For example, the works with Office 365 program identity providers might offer different MFA solutions that you can manage according to the identity provider's specifications. For more information, see http://go.microsoft.com/fwlink/p/?LinkId=510953.
A26: Authentication IA | B26: AzureAD | C26: Phone Factor | D26: Make the connection to a specific user stronger by using a second factor that can be presented by the user when responding to a call. Any of the following may be used for the second factor of authentication: - Call my mobile phone. The user receives a phone call that asks them to press the pound key. Once the pound key is pressed, the user is logged in. - Text code to my mobile phone. The user receives a text message containing a six-digit code that they must enter into the portal. - Call my office phone. This is the same as Call my mobile phone, but it enables the user to select a different phone if they do not have their mobile phone with them. - Notify me through app. The user configured a smartphone app and they receive a notification in the app that they must confirm the login. Smartphone apps are available for Windows Phone, iPhone, and Android devices. - Show one-time code in app. The same smartphone app is used. Instead of receiving a notification, the user starts the app and enters the six-digit code from the app into the portal. | E26: Multi Factor Portal
A27: Authentication IA | B27: AzureAD | C27: Mobile App | D27: Make the connection to a specific user stronger by using a second factor that can be presented to an app running on the user's smartphone. Any of the following may be used for the second factor of authentication: - Call my mobile phone. The user receives a phone call that asks them to press the pound key. Once the pound key is pressed, the user is logged in. - Text code to my mobile phone. The user receives a text message containing a six-digit code that they must enter into the portal. - Call my office phone. This is the same as Call my mobile phone, but it enables the user to select a different phone if they do not have their mobile phone with them. - Notify me through app. The user configured a smartphone app and they receive a notification in the app that they must confirm the login. Smartphone apps are available for Windows Phone, iPhone, and Android devices. - Show one-time code in app. The same smartphone app is used. Instead of receiving a notification, the user starts the app and enters the six-digit code from the app into the portal. | E27: Multi Factor Portal
A28: Authentication IA | B28: AzureAD | C28: Text Message Second Factor | D28: Make the connection to a specific user stronger by using a second factor that can be presented by that user via a text message. Any of the following may be used for the second factor of authentication: - Call my mobile phone. The user receives a phone call that asks them to press the pound key. Once the pound key is pressed, the user is logged in. - Text code to my mobile phone. The user receives a text message containing a six-digit code that they must enter into the portal. - Call my office phone. This is the same as Call my mobile phone, but it enables the user to select a different phone if they do not have their mobile phone with them. - Notify me through app. The user configured a smartphone app and they receive a notification in the app that they must confirm the login. Smartphone apps are available for Windows Phone, iPhone, and Android devices. - Show one-time code in app. The same smartphone app is used. Instead of receiving a notification, the user starts the app and enters the six-digit code from the app into the portal. Make the connection to a specific user stronger by using a second factor that can be presented by that user via a text message. | E28: Multi Factor Portal
A29: Authentication IA | B29: AzureAD | C29: Conditional Access | D29: Conditional Access enables organizations to assess whether users are connecting with trusted devices and to block devices outside of policy. Personally owned devices of your users can be marked known to your organization by requiring the users to work place join their devices to the Azure Active Directory Device Registration service. Azure Active Directory Device Registration is the foundation for device-based conditional access scenarios. When a device is registered, Azure Active Directory Device Registration provisions the device with an identity which is used to authenticate the device when the user signs in. The authenticated device, and the attributes of the device, can then be used to enforce conditional access policies for applications that are hosted in the cloud and on-premises. When combined with a Mobile Device Management solution such as Intune, the device attributes in Azure Active Directory will be updated with additional information about the device. This allows you to create conditional access rules that enforce access from devices will meet your standards for security and compliance. Azure Active Directory Device Registration is available in your Azure Active Directory. The service includes support for iOS, Android, and Windows devices.
A30: Authentication IA | B30: SharePoint | C30: Conditional Access SharePoint | D30: Conditional access in SharePoint and OneDrive goes beyond user permissions: it is based on a combination of factors, such as the identity of a user or group, the network that the user is connected to, the device and application they are using, and the type of data they are trying to access. The access granted to the user adapts to this broader set of conditions. With location-based conditional access policies in SharePoint Online, you can limit access to specific corporate networks or locations. For example, if you restrict access to only your corporate network, users will not be able to access organizational data when they leave the office. This policy helps you prevent access to organization’s data from rogue or insecure networks. | F30: Set-SPOTenant- IPAddressEnforcement $true|$false, Set-SPOTenant -IPAddressAllowList “IPList” | G30: Get-SPOTenant
A31: Authentication IA | B31: Exchange | C31: Conditional Access Exchange | D31: Client access rules are like transport rules for client connections to your organization. You use conditions and exceptions to identify the connections based on the user or properties of the client or the connection, and actions that define what to do with those connections. You need to be assigned permissions before you can run this cmdlet. Although all parameters for this cmdlet are listed in this topic, you may not have access to some parameters if they're not included in the permissions assigned to you. Access the administrative documentation set for your Exchange Online release to review the Managing Client Access Rules self-service administration article to determine which role based access control (RBAC) role assignment is required
A32: Authentication IA | B32: AzureAD | C32: Conditional Access Mobile Devices | D32: Conditional Access enables organizations to assess whether users are connecting with trusted devices and to block devices outside of policy. Personally owned devices of your users can be marked known to your organization by requiring the users to work place join their devices to the Azure Active Directory Device Registration service. Azure Active Directory Device Registration is the foundation for device-based conditional access scenarios. When a device is registered, Azure Active Directory Device Registration provisions the device with an identity which is used to authenticate the device when the user signs in. The authenticated device, and the attributes of the device, can then be used to enforce conditional access policies for applications that are hosted in the cloud and on-premises. When combined with a Mobile Device Management solution such as Intune, the device attributes in Azure Active Directory will be updated with additional information about the device. This allows you to create conditional access rules that enforce access from devices will meet your standards for security and compliance. Azure Active Directory Device Registration is available in your Azure Active Directory. The service includes support for iOS, Android, and Windows devices. | E32: Compliance Center
A33: Identity IA | B33: AzureAD | C33: Disable Identities that are not active | D33: Reduce the number of active identities to reduce licensing costs and the identity attack surface. Periodically check for inactive users and disable accounts that are not active. For example, in Exchange Online, you can use the Get-StaleMailboxDetailReport cmdlet to view mailboxes that have not been accessed for at least the last 30 days. Identities for inactive mailboxes should be disabled. | E33: Inactive Mailbox Report | G33: Get-SpoActiveUserReport, Get-CsActiveUserReport, Get-StaleMailboxDetailReport
A34: Identity IA | B34: AzureAD | C34: Use dedicated Administrative accounts | D34: Do not elevate accounts used for user collaboration to admin privileges use dedicated identities for administrative accounts. Use a naming convention that make them discoverable. | G34: Get-MsolUser -Filter, Get-MailboxActivityReport
A35: Identity IA | B35: Office365 | C35: More than one Tenant Admin Designated | D35: Delegate Admin privileges to more than user in case that the primary admin cannot fulfil the administrative duties.
A36: Identity IA | B36: Office 365 | C36: More than 5 Tenant Admins | D36: Keep the number of high privileged administrators to a minimum to make the attack surface smaller.
A37: Users AC | B37: Exchange | C37: Inspect Mailbox Permissions | D37: Prevent unlawful information disclosure by regularly reviewing all mailbox permissions to ensure that the only appropriate permissions are set. Unusual or unexpected users or permissions should be investigated immediately. | G37: Get-MailboxFolderPermission
A38: Users AC | B38: Exchange | C38: Disable Remote PowerShell | D38: Remote PowerShell enables you to manage your Exchange Online organization from the command line. By default, all accounts you create in Exchange Online are allowed to use remote Shell to access your Exchange Online organization. You can enable or disable a user’s ability to connect to your Exchange Online organization using remote Shell. Disable PowerShell for all users and applications that do not need it. This will reduce the potential attack surface. Some client-side applications may use PowerShell functionality so perform an assessment before disabling. Skype for Business Online, SharePoint Online, and Azure disable access to PowerShell for non-administrators by default. | F38: Get-Content <text file> | Set-User -RemotePowerShellEnabled $false | G38: Get-User -ResultSize unlimited -Filter {RemotePowerShellEnabled -eq $true}
A39: Users AC | B39: Exchange | C39: Disable E-mail client protocols | D39: Reducing the attack surface of your tenant is important from both a security and a compliance standpoint. Disable un-used client access protocols for Exchange Online to limit the attack surface of your tenant.
A40: Users AC | B40: SharePoint | C40: Manage User Access SharePoint | D40: Understand how SharePoint permissions are built on the concepts of SharePoint groups, Permission levels and Permissions inheritance and site structure. Customize permission settings to better reflect the requirements of your organization. For example, you can stop permission inheritance at a specific location, and you can create new groups and new permission levels.
...

Sheet Data Leakage
A1: Category | B1: Product | C1: Consideration | D1: Description | E1: Portal Configuration | F1: PS Configure | G1: PS Get | H1: Assessed
A2: Phishing ATP | B2: Office 365 | C2: Anti Spam/Phishing/Anti Malware (ATP) | D2: One of the most common causes that accounts and systems are compromised is due to Phishing campaigns. To meet the risks surrounding phishing and malware Office 365 has a robust set of tools to meet these advanced threats. Organizations need to educate users and implement safe guards to meet acceptable risk levels.
A3: Phishing ATP | B3: Exchange | C3: User Education | D3: It is key to educate users about phishing attacks, malicious and unwanted email, and to recognize possible scams. This enables users to determine for themselves what actions to take if they come across a phishing attempt or other similar scam. Internal notifications can help users with identification and early eradication of a threat.
A4: Phishing ATP | B4: Exchange | C4: ATP Protection | D4: Exchange Online Advanced Threat Protection protects mailboxes against new, sophisticated attacks in real-time by protecting against unsafe attachments and malicious links. All suspicious content goes through a real-time behavioral malware analysis that uses machine learning techniques to evaluate the content for suspicious activity. While the content is being scanned, the URLs are rewritten to go through Office 365. The URLs are examined in real time, at the time a user clicks them. Gain critical insights into who is being targeted in your organization and the category of attacks you are facing.
A5: Phishing ATP | B5: Exchange | C5: Detonation Chamber | D5: Exchange Online Advanced Threat Protection protects mailboxes against new, sophisticated attacks in real-time by protecting against unsafe attachments and malicious links. All suspicious content goes through a real-time behavioral malware analysis that uses machine learning techniques to evaluate the content for suspicious activity. Unsafe attachments are sandboxed in a detonation chamber before being sent to recipients.
A6: Phishing ATP | B6: Exchange | C6: Safe Links | D6: Exchange Online Advanced Threat Protection protects mailboxes against new, sophisticated attacks in real-time by protecting against unsafe attachments and malicious links. Safe Links help protect environments when users click a link. While the content is being scanned, the URLs are rewritten to go through Office 365. The URLs are examined in real-time, at the time a user clicks them. If a link is unsafe, the user is warned not to visit the site or informed that the site has been blocked.
A7: Phishing ATP | B7: Exchange | C7: Rich reporting and URL trace capabilities | D7: Exchange Online Advanced Threat Protection protects mailboxes against new, sophisticated attacks in real-time by protecting against unsafe attachments and malicious links. Reports of how your users are accessing different URLs from their mailboxes for getting a clear picture on what type of users are getting targeted. Also, you get details on what messages have been blocked due to unknown viruses or malware. | E7: ECP select mail flow and then url trace
A8: Phishing ATP | B8: Exchange | C8: Exchange Online Protection Configuration Best Practices | D8: Exchange Online Protection (EOP) is a cloud-hosted email filtering service built to protect customers from spam, phishing and malware, and to implement custom policy rules. Proper configuration of EOP is essential to keep out unwanted e-mail and keep the messaging system secure. Follow Microsoft's recommended best practices for configuring EOP features such as anti-spam, anti-malware, phishing and spoofing prevention, and more.
A9: Phishing ATP | B9: Exchange | C9: End User Spam Notification | D9: You can configure end-user spam notifications for the default company-wide content filter policy or for custom content filter policies that are applied to domains. Enabling end-user spam notification messages lets your end users self-manage their own spam-quarantined messages. End-user spam notifications cannot be used with policies applied to users or groups, or to a policy with exceptions.
A10: Phishing ATP | B10: Exchange | C10: Zero-hour Auto Purge (ZAP) | D10: ZAP change the verdict of an unread email from Clean to Spam and move this message from your Inbox to the Junk Email folder. This goes the other way around as well, so if a message was incorrectly marked as Spam (False Negative) and it was moved to Junk Email folder, ZAP will move the message in your Inbox folder. | F10: Set-HostedContentFilterPolicy | G10: Get-HostedContentFilterPolicy
A11: Phishing ATP | B11: Exchange | C11: Advanced spam filtering options | D11: Advanced spam filtering (ASF) options give administrators the ability to inspect various content attributes of a message. The presence of these attributes in a message either increases the spam score of the message (thereby increasing the potential for it to be identified as spam) or marks the message as spam. The ASF options target specific message properties, such as HTML tags and URL redirection, which are commonly found in spam messages. | E11: Protection Spam Filter
A12: Phishing ATP | B12: Exchange | C12: Setup SPF Record | D12: SPF records are TXT records that help to prevent other people from using your domain to send spam or other malicious email. Sender policy framework (SPF) records work by identifying the servers that are authorized to send email from your domain. An email system that receives an email from your domain looks at the SPF record, and if the email server that sent the message was an Office 365 server, the message is accepted. If the server that sent the message was your old mail system or a malicious system on the Internet, the message is considered un-safe. | E12: Select the domain click Find and Fix
A13: Phishing ATP | B13: Exchange | C13: SPF Record: Hard Fail | D13: When this setting is enabled, messages that fail an SPF check (meaning they were sent from an IP address not specified in the SPF record) will be marked as spam. Turning this setting on is recommended for organizations who are concerned about receiving phishing messages. SPF catches the case where the phisher spoofs the 5321 MailFrom. | E13: Navigate to Protection/ Spam filter
A14: Phishing ATP | B14: Exchange | C14: Conditional Sender ID filtering | D14: When this setting is enabled, any message that hard fails a conditional Sender ID check is marked as spam. This option combines an SPF check with a Sender ID check to help protect against message headers that contain forged senders. | E14: Navigate to Protection/ Spam filter
A15: Phishing ATP | B15: Exchange | C15: DKIM | D15: Exchange Online support inbound validation of Domain Keys Identified Mail (DKIM) messages. DKIM is a method for validating that a message was sent from the domain it says it originated from and that it was not spoofed by someone else. It ties an email message to the organization responsible for sending it. DKIM verification is automatically used for all messages sent over IPv6 communications.
A16: Phishing ATP | B16: Exchange | C16: DMARC | D16: DMARC is a technology designed to combat email spoofing and is useful to stop phishing. Specifically, it protects the case where a phisher has spoofed the 5322.From email address, which is the email address displayed in mail clients.
A17: Phishing ATP | B17: Exchange | C17: Top senders and recipients | D17: The top senders and recipients report can provide indications of e-mails being forwarded outside of the organization or other patterns that may indicate leakage of information.
A18: Phishing ATP | B18: Exchange | C18: Malware & SPAM Detections | D18: The malware and SPAM report may provide insight if particular users are more targeted than others within the organization. This may lead to more direct actions to educate the users affected as well as setting stricter Outlook rules.
A19: Phishing ATP | B19: Exchange | C19: Remove Potential Phishing messages | D19: In the case that a phishing campaign has by passed the defenses use the data leakage process to identify and remove the messages from the system. Check flags such as read status to understand how many people may have been exposed.
A20: Phishing ATP | B20: Exchange | C20: PowerShell cmdlets for Phishing and Anti Spam | D20: This is a reference to the PowerShell cmdlets available to configure anti-spam and anti-malware settings in Exchange Online.
A21: Client CM | B21: Client | C21: 10 immutable laws of security | D21: Do not forget the 10 immutable laws of security when you are securing your workstations. Ensure that the appropriate awareness trainings are done and settings that help users to adhere to them are in place.
A22: Client CM | B22: Client | C22: Windows Information Protection (WIP) | D22: Windows Information Protection (WIP), helps to protect against this potential data leakage without otherwise interfering with the employee experience. WIP also helps to protect enterprise apps and data against accidental data leak on enterprise-owned devices and personal devices that employees bring to work without requiring changes to your environment or other apps. Finally, another data protection technology, Azure Rights Management also works alongside WIP to extend data protection for data that leaves the device, such as when email attachments are sent from an enterprise aware version of a rights management mail client.
A23: Client CM | B23: Client | C23: Intune integration with Lookout | D23: You can control access from mobile devices to corporate resources, based on risk assessment conducted by Lookout, a device threat protection solution that is integrated with Microsoft Intune. The risk is based on telemetry that the Lookout service collects from devices for operating system (OS) vulnerabilities, installed malicious apps, and malicious network profiles. Based on Lookout's reported risk assessment enabled through Intune compliance policies, you can configure conditional access policies in Intune and allow or block devices that have been determined to be noncompliant due to threats detected on those devices.
A24: Data Loss DP | B24: Office 365 | C24: Data Loss Prevention (DP) | D24: Data loss prevention (DLP) is an important function for organizations to safeguard theirs and their customer’s information. Office 365 contains a rich feature set that can warn users if they are about to do something that violate policy as well as enforcing policy where necessary.
A25: Data Loss DP | B25: Exchange | C25: Data Loss Prevention Exchange | D25: Data loss prevention (DLP) is an important issue for many customers because of the extensive use of email for business critical communication that includes sensitive data. Exchange Online contains a number of DLP features that help organizations enforce policies, and analyze how users adhere to those policies. | E25: Compliance Management select Data Loss Prevention
A26: Data Loss DP | B26: Exchange | C26: DLP Procedures | D26: Data loss prevention (DLP) includes built-in templates and customizable policies to meet an organization's need to identify sensitive content. DLP policies are simple packages that contain sets of conditions, which are made up of transport rules, actions, and exceptions that you create in the Exchange admin center and then activate to filter email messages and attachments. You can also inform email senders that they may be about to violate one of your policies—even before they send an offending message by configuring Policy Tips. Policy Tips can be configured to present a brief note in Outlook, Outlook on the web, and OWA for devices, that provides information about possible policy violations during message creation. | E26: Compliance Management select Data Loss Prevention
A27: Data Loss DP | B27: Exchange | C27: DLP Policy Templates | D27: You can use data loss prevention (DLP) policy templates to get started with your DLP solution in Exchange Online. A DLP policy template is a model for a policy. You can select a template to begin the process of building your own customized DLP policy. Within your DLP policy, you can customize the rules to ensure that it meets your business needs for data loss prevention. Several policy templates are supplied by Microsoft, but these are not the only way to implement a data loss prevention solution in Exchange. Third-party templates and Windows File Classification Infrastructure templates can be imported to help prevent information from being leaked. | E27: Compliance Management select Data Loss Prevention
A28: Data Loss DP | B28: Exchange | C28: Keyword matching | D28: Data loss prevention (DLP) in Office 365 includes 80 sensitive information types that are ready for you to use in DLP policies. A sensitive information type is defined by a pattern that can be identified by a regular expression or a function. In addition, corroborative evidence such as keywords and checksums can be used to identify a sensitive information type. Confidence level and proximity are also used in the evaluation process. | E28: Compliance Management select Data Loss Prevention
A29: Data Loss DP | B29: Exchange | C29: Regular expression matching | D29: The flexibility of regular expression matching makes this a common choice for implementing matches for data such as driver’s license numbers, addresses and credit card numbers. Common regular expression syntax is used to define the regex patterns. | E29: Compliance Management select Data Loss Prevention
A30: Data Loss DP | B30: Exchange | C30: Structured data fingerprinting | D30: Document Fingerprinting makes it easier for organizations to protect information by identifying standard for Information Protection that are used within the organization. Document Fingerprinting is a Data Loss Prevention (DLP) feature that converts a standard form into a sensitive information type, which you can use to define transport rules and DLP policies. For example, you can create a document fingerprint based on a blank patent template and then create a DLP policy that detects and blocks all outgoing patent templates with sensitive content filled in. | E30: Compliance Management select Data Loss Prevention
A31: Data Loss DP | B31: Exchange | C31: Policy Tip | D31: Policy Tips are informative notices that are displayed to email senders while they’re composing a message. The purpose of the Policy Tip is to educate users that they might be violating the business practices or policies that you are enforcing with the data loss prevention (DLP) policies that organizations have established. | E31: Compliance Management select Data Loss Prevention
A32: Data Loss DP | B32: Exchange | C32: Report attempted Policy Violations | D32: View information about the number of messages that are detected by your data loss prevention (DLP) policies. This includes DLP policy matches and DLP rules matches for sent mail and received mail. You can also view the number of matches, overrides, and false positives for each policy within the past 24 hours in the Exchange Admin Center. | E32: Top DLP Policies
A33: Data Loss DP | B33: Exchange | C33: DLP Matches by Severity for Mail | D33: View information about the number of messages that are detected by your data loss prevention (DLP) policies. This includes DLP policy matches and DLP rules matches for sent mail and received mail. You can also view the number of matches, overrides, and false positives for each policy within the past 24 hours in the Exchange Admin Center. In addition, some reports are grouped by severity. The DLP Matches by Severity for Mail report is an example of a report that groups policy and rule matches based on severity. | E33: Matches based on Severity
A34: Data Loss DP | B34: Exchange | C34: Attachment handling Outlook on the web | D34: Administrators can set up both private and public attachment handling in Outlook on the web depending on how you configure your Outlook on the web mailbox policies. The settings for private (internal) and public (external) networks define how users can open, view, send, or receive attachments depending on whether a user is signed in to Outlook on the web on a computer that is part of a private or of a public network. This setting can be used to restrict access to documents from public networks as an example.
A35: Data Loss DP | B35: Exchange | C35: Attachment handling Exchange ActiveSync | D35: In Office 365, you can create mobile device mailbox policies to apply a common set of policies or security settings to a collection of users. A default mobile device mailbox policy is created in every Office 365 organization. Administrators can create policies to block attachments from being synchronized to mobile devices to limit exposure.
A36: Data Loss DP | B36: SharePoint | C36: Data Loss Prevention SharePoint | D36: Data loss prevention (DLP) in SharePoint Online provides you with a way to identify that data, so you can work with document owners to reduce any risk to your organization. DLP enables organizations to search and report on sensitive content.
A37: Data Loss DP | B37: Office | C37: DLP in Office 2016 applications | D37: Administrators can set up policies for SharePoint Online and OneDrive for Business that automatically apply to Word, Excel and PowerPoint 2016 applications. If users open a sensitive file from SharePoint Online or OneDrive for Business, they will be notified of the sensitive information in context within the Office application. Depending on the policy, the user can simply choose to ignore the policy or be asked to provide a business justification in order to continue working on the sensitive data. Users also have the option of turning off notification policies from within the Office applications. With these advanced capabilities, you will have the ability to create DLP policies across different services while maintaining a productive end-user experience.
A38: Data Loss DP | B38: Office | C38: Policy Tip | D38: Policy Tips are in-context notifications that educate users as soon as potential policy matches are detected while working in Excel, PowerPoint, and Word. For example, if you’re working in a spreadsheet that contains credit card numbers, Excel can notify you about the sensitive information before it is shared with others.
A39: Data Loss DP | B39: Office 365 | C39: Plan for File Classification | D39: File Classification Infrastructure uses classification rules to automatically scan files and classify them according to the contents of the file. Classification properties are defined centrally in Active Directory so that these definitions can be shared across file servers in the organization. You can create classification rules that scan files for a standard string or for a string that matches a pattern (regular expression). When a configured classification parameter is found in a file, that file is classified as configured in the classification rule. When deploying file classification across an organization, start by identifying the information that should be classified and the appropriate classification methods that should be used. Be sure to ensure that you consider any regulations, such as HIPAA, while you are listing the classification requirements.
A40: Data Loss DP | B40: Office 365 | C40: Azure Information Protection Classification | D40: Classify data based on source, context, and content at the time of creation or modification, either automatically or manually. Once classified, a persistent label is embedded in the data and actions such as visual marking and encryption can be taken based on the classification and label.
...

Sheet Security & Compliance
A1: Category | B1: Product | C1: Feature | D1: Description | E1: Portal | F1: PS Configure | G1: PS Get | H1: Assessed
A2: Auditing AU | B2: Office 365 | C2: Auditing (AU) | D2: The Auditing category covers key aspects of information security that enable examination and re-creation of events. Auditing allow organizations to solve issues as well as to detect and investigate security issues and incidents. If reviewing this from the FedRAMP view please go to the full Customer Security Considerations view.
A3: Auditing AU | B3: AzureAD | C3: Azure AD | D3: Use Azure Active Directory (Azure AD) access and usage reports to gain visibility into the integrity and security of your organization’s directory. With this information, a directory admin can better determine where possible security risks may lie so that they can adequately plan to mitigate those risks. Audit all account actions and use Azure AD reports to identify potential fraudulent activities.
A4: Auditing AU | B4: AzureAD | C4: Azure AD Audit Events | D4: Identify privileged actions that occur in Azure Active Directory, including elevation changes, password changes, and so forth. Automate this process by consuming the security audit feed with a Security Information and Event Management system. (SIEM)
A5: Auditing AU | B5: AzureAD | C5: Review Sign-Ins from unknown sources | D5: Use this report to identify users who have successfully signed in to your organization while assigned a client IP address that has been recognized by Microsoft as an anonymous proxy IP address. These proxies are often used by users who want to hide their computer’s IP address.
A6: Auditing AU | B6: AzureAD | C6: Review Sign-ins after multiple failures | D6: Use this report to identify users who have successfully signed in after multiple consecutive failed sign-in attempts.
A7: Auditing AU | B7: AzureAD | C7: Review Signs-ins from multiple geographies | D7: Use this report to identify successful sign-in activities from a user where two sign ins appeared to originate from different countries and the time between the sign ins makes it impossible for the user to have travelled between those countries.
A8: Auditing AU | B8: AzureAD | C8: Review AAD Logons for Anomalies | D8: Indicates users whose accounts may have been compromised.
A9: Auditing AU | B9: Exchange | C9: Exchange | D9: Leverage the rich set of auditing features in Exchange Online to audit administrator, user, application, and external user access. For example, you can use audit logging to troubleshoot configuration issues by tracking specific changes made by administrators, and to help you meet regulatory, compliance, and litigation requirements. Exchange Online includes both administrator audit logging and mailbox audit logging. These logs can help you determine who has accessed a mailbox and what they’ve done.
A10: Auditing AU | B10: Exchange | C10: Exchange Online Privileged Administrator changes | D10: You can search the administrator audit logs to discover who made changes to organization, server, and recipient configuration. This can be helpful when you're trying to track the cause of unexpected behavior, to identify a malicious administrator, or to verify that compliance requirements are being met. Regularly review all changes to privileged role groups to detect potentially harmful changes.
A11: Auditing AU | B11: Exchange | C11: {=[1]!'!CSC Main!R44C3'} -> #REF! | D11: These are the activities that can be logged by mailbox audit logging and searched through the Audit Log Search, by default mailbox audit logging is not turned on. Copied messages to another folder, Created item, Deleted messages from Deleted Items folder, Moved messages to another folder, Moved messages to Deleted Items folder, Purged messages from the mailbox, Sent message using Send As permissions, Sent message using Send On Behalf permissions, Updated message, User signed in to mailbox
A12: Auditing AU | B12: Exchange | C12: Detect non-owner mailbox access | D12: Audit non-owner access activity to identify potential leaks of information and to proactively review non-owner access to mailboxes. The Non-Owner Mailbox Access Report in the Exchange Admin Center lists the mailboxes that have been accessed by someone other than the person who owns the mailbox. When a mailbox is accessed by a non-owner, Exchange logs information about this action in a mailbox audit log that’s stored as an email message in a hidden folder in the mailbox being audited. Entries from this log are displayed as search results and include a list of mailboxes accessed by a non-owner, who accessed the mailbox and when, the actions performed by the non-owner, and whether the action was successful. By default, entries in the mailbox audit log are retained for 90 days. | F12: Get-Mailbox -ResultSize Unlimited -Filter {RecipientTypeDetails -eq "UserMailbox"} | Set-Mailbox -AuditEnabled $true | G12: Get-Mailbox | FT Name,AuditEnabled
A13: Auditing AU | B13: Exchange | C13: Detect changes to eDiscovery and legal hold | D13: Your organization may require all mailbox data to be preserved for a specific period. You can use Litigation Hold or In-Place Hold to meet this requirement. After you place a mailbox on Litigation Hold or In-Place Hold, mailbox items that are modified or that are permanently deleted are preserved in the Recoverable Items folder. Use the hold report to keep track of when Hold is enabled or disabled in a given time period. For each of these change types, the report includes the user who made the change and the time and date the change was made. Regularly review the report to audit changes to eDiscovery and Hold settings to ensure that users that should be under Hold remain under Hold.
A14: Auditing AU | B14: Exchange | C14: List mailboxes under hold | D14: Your organization may require all mailbox data to be preserved for a specific period. You can use Litigation Hold or In-Place Hold to meet this requirement. After you place a user on Litigation Hold or In-Place Hold, mailbox items that are modified or that are permanently deleted are preserved in the Recoverable Items folder. If your organization is required to keep users under Hold, regularly review the Hold report to audit changes to settings.
A15: Auditing AU | B15: Exchange | C15: Review configuration changes in organization | D15: You can use the Exchange Admin Center to search for and view entries in the administrator audit log. The administrator audit log records specific actions, based on Exchange Management Shell cmdlet, performed by administrators and users who have been assigned administrative privileges. Entries in the administrator audit log provide you with information about what cmdlet was run, which parameters were used, who ran the cmdlet, and what objects were affected. Regularly review all configuration changes to ensure that only valid and approved changes have been made to the organization's settings. | G15: Get-AdminAuditLogConfig | FL AdminAuditLogEnabled
A16: Auditing AU | B16: Exchange | C16: Review mailbox access by datacenter administrators | D16: In Exchange Online, actions performed by Microsoft and delegated administrators are logged in the administrator audit log. You can use the Exchange Admin Center or PowerShell to search for and view audit log entries to determine if external administrators performed any actions on or changed the configuration of your Exchange Online organization. You can also use PowerShell to export these audit log entries. Regularly audit all activities performed by external administrators, including Microsoft service administrators. | G16: Search-AdminAuditLog -ExternalAccess $true
A17: Auditing AU | B17: Office 365 | C17: Office 365 User administration activities | D17: These are the administration activities that are logged when an admin adds or changes a user account. Added user, Changed user license, Changed user password, Deleted user, Reset user password, Set property that forces user to change password, Set license properties, Updated user. These activities can be used to review administrator activity on a regular basis to ensure that the activities performed are in accordance to organizational principles.
A18: Auditing AU | B18: Office 365 | C18: Office 365 Group administration activities | D18: Search these logs to identify activities related to an admin or a user creates or changes an Office 365 group or when an admin creates a security group. The activities logged are Added group, Added member to group, Deleted group, Removed member from group, Updated group
A19: Auditing AU | B19: Office 365 | C19: Application administration activities | D19: When an administrator adds or changes an application that's registered in Azure AD these activities are logged. Added delegation entry, Added service principal, Added service principal credentials, Removed delegation entry, Removed service principal, Removed service principal credentials, Set delegation entry. Keeping track of these entries are important since applications can be used to access customer data hence a rouge admin could use applications in an attempt to circumvent security. Both the registration of applications and actions carried by the applications like accessing customer data are logged.
A20: Auditing AU | B20: Office 365 | C20: Office 365 Role administration activities | D20: It is important to keep track of the Azure AD roles in Office 365 to detect potential attempts to elevate permissions. The role administration logging is logging the following activities Add member to Role, Removed a user from a directory role, Set company contact information.
