Workbook
Name KEY_Control_Frequency: KEY!$E$17:$E$24
Name KEY_Control_Function: KEY!$C$17:$C$22
Name KEY_Control_Owner: KEY!$H$17:$H$21
Name KEY_Control_Status: KEY!$G$17:$G$20
Name KEY_Control_Type: KEY!$A$17:$A$19
Name Key_Risk_Irating: KEY!$J$3:$J$7
Name KEY_Risk_Lrating: KEY!$G$3:$G$7
Name KEY_Risk_Rating: KEY!$C$3:$C$7
Name KEY_Risk_Source: KEY!$A$3:$A$7
Name KEY_Risk_Status: KEY!$E$3:$E$8
Name Slicer_SOURCE: #N/A
Name Slicer_Status: #N/A

Sheet Index
B1: RISK INDEX
B2: Category | C2: Threat ID | D2: Threat Action | E2: TOTAL Risks | F2: HIGH Risks | G2: MED Risks | H2: LOW Risks | I2: Unaddressed Risks
B3: Physical | C3: PHY-001 | D3: Loss of Property | E3: =COUNTIF('Risk Register'!#REF!,"*"&C3&"*") -> #REF! | F3: =COUNTIFS('Risk Register'!#REF!,"*"&C3&"*",'Risk Register'!M:M,">=16") -> #REF! | G3: =COUNTIFS('Risk Register'!#REF!,"*"&C3&"*",'Risk Register'!M:M,">=7",'Risk Register'!M:M,"<=15") -> #REF! | H3: =COUNTIFS('Risk Register'!#REF!,"*"&C3&"*",'Risk Register'!M:M,"<=6") -> #REF! | I3: =SUM(COUNTIFS('Risk Register'!#REF!,"*"&C3&"*",'Risk Register'!S6:S55,{"Not Considered","Partial Controls"})) -> #REF!
B4: Physical | C4: PHY-002 | D4: Theft of Property | E4: =COUNTIF('Risk Register'!#REF!,"*"&C4&"*") -> #REF! | F4: =COUNTIFS('Risk Register'!#REF!,"*"&C4&"*",'Risk Register'!M:M,">=16") -> #REF! | G4: =COUNTIFS('Risk Register'!#REF!,"*"&C4&"*",'Risk Register'!M:M,">=7",'Risk Register'!M:M,"<=15") -> #REF! | H4: =COUNTIFS('Risk Register'!#REF!,"*"&C4&"*",'Risk Register'!M:M,"<=6") -> #REF!
B5: Physical | C5: PHY-003 | D5: Accidental Destruction of Property | E5: =COUNTIF('Risk Register'!#REF!,"*"&C5&"*") -> #REF! | F5: =COUNTIFS('Risk Register'!#REF!,"*"&C5&"*",'Risk Register'!M:M,">=16") -> #REF! | G5: =COUNTIFS('Risk Register'!#REF!,"*"&C5&"*",'Risk Register'!M:M,">=7",'Risk Register'!M:M,"<=15") -> #REF! | H5: =COUNTIFS('Risk Register'!#REF!,"*"&C5&"*",'Risk Register'!M:M,"<=6") -> #REF!
B6: Physical | C6: PHY-004 | D6: Natural Destruction of Property | E6: =COUNTIF('Risk Register'!#REF!,"*"&C6&"*") -> #REF! | F6: =COUNTIFS('Risk Register'!#REF!,"*"&C6&"*",'Risk Register'!M:M,">=16") -> #REF! | G6: =COUNTIFS('Risk Register'!#REF!,"*"&C6&"*",'Risk Register'!M:M,">=7",'Risk Register'!M:M,"<=15") -> #REF! | H6: =COUNTIFS('Risk Register'!#REF!,"*"&C6&"*",'Risk Register'!M:M,"<=6") -> #REF!
B7: Physical | C7: PHY-005 | D7: Intentional Destruction of Property | E7: =COUNTIF('Risk Register'!#REF!,"*"&C7&"*") -> #REF! | F7: =COUNTIFS('Risk Register'!#REF!,"*"&C7&"*",'Risk Register'!M:M,">=16") -> #REF! | G7: =COUNTIFS('Risk Register'!#REF!,"*"&C7&"*",'Risk Register'!M:M,">=7",'Risk Register'!M:M,"<=15") -> #REF! | H7: =COUNTIFS('Risk Register'!#REF!,"*"&C7&"*",'Risk Register'!M:M,"<=6") -> #REF!
B8: Physical | C8: PHY-006 | D8: Intentional Sabotage of Property | E8: =COUNTIF('Risk Register'!#REF!,"*"&C8&"*") -> #REF! | F8: =COUNTIFS('Risk Register'!#REF!,"*"&C8&"*",'Risk Register'!M:M,">=16") -> #REF! | G8: =COUNTIFS('Risk Register'!#REF!,"*"&C8&"*",'Risk Register'!M:M,">=7",'Risk Register'!M:M,"<=15") -> #REF! | H8: =COUNTIFS('Risk Register'!#REF!,"*"&C8&"*",'Risk Register'!M:M,"<=6") -> #REF!
B9: Physical | C9: PHY-007 | D9: Intentional Vandalism of Property | E9: =COUNTIF('Risk Register'!#REF!,"*"&C9&"*") -> #REF! | F9: =COUNTIFS('Risk Register'!#REF!,"*"&C9&"*",'Risk Register'!M:M,">=16") -> #REF! | G9: =COUNTIFS('Risk Register'!#REF!,"*"&C9&"*",'Risk Register'!M:M,">=7",'Risk Register'!M:M,"<=15") -> #REF! | H9: =COUNTIFS('Risk Register'!#REF!,"*"&C9&"*",'Risk Register'!M:M,"<=6") -> #REF!
B10: Physical | C10: PHY-008 | D10: Electrical System Failure | E10: =COUNTIF('Risk Register'!#REF!,"*"&C10&"*") -> #REF! | F10: =COUNTIFS('Risk Register'!#REF!,"*"&C10&"*",'Risk Register'!M:M,">=16") -> #REF! | G10: =COUNTIFS('Risk Register'!#REF!,"*"&C10&"*",'Risk Register'!M:M,">=7",'Risk Register'!M:M,"<=15") -> #REF! | H10: =COUNTIFS('Risk Register'!#REF!,"*"&C10&"*",'Risk Register'!M:M,"<=6") -> #REF!
B11: Physical | C11: PHY-009 | D11: HVAC Failure | E11: =COUNTIF('Risk Register'!#REF!,"*"&C11&"*") -> #REF! | F11: =COUNTIFS('Risk Register'!#REF!,"*"&C11&"*",'Risk Register'!M:M,">=16") -> #REF! | G11: =COUNTIFS('Risk Register'!#REF!,"*"&C11&"*",'Risk Register'!M:M,">=7",'Risk Register'!M:M,"<=15") -> #REF! | H11: =COUNTIFS('Risk Register'!#REF!,"*"&C11&"*",'Risk Register'!M:M,"<=6") -> #REF!
B12: Physical | C12: PHY-010 | D12: Structural Facility Failure | E12: =COUNTIF('Risk Register'!#REF!,"*"&C12&"*") -> #REF! | F12: =COUNTIFS('Risk Register'!#REF!,"*"&C12&"*",'Risk Register'!M:M,">=16") -> #REF! | G12: =COUNTIFS('Risk Register'!#REF!,"*"&C12&"*",'Risk Register'!M:M,">=7",'Risk Register'!M:M,"<=15") -> #REF! | H12: =COUNTIFS('Risk Register'!#REF!,"*"&C12&"*",'Risk Register'!M:M,"<=6") -> #REF!
B13: Physical | C13: PHY-011 | D13: Water Distribution System Failure | E13: =COUNTIF('Risk Register'!#REF!,"*"&C13&"*") -> #REF! | F13: =COUNTIFS('Risk Register'!#REF!,"*"&C13&"*",'Risk Register'!M:M,">=16") -> #REF! | G13: =COUNTIFS('Risk Register'!#REF!,"*"&C13&"*",'Risk Register'!M:M,">=7",'Risk Register'!M:M,"<=15") -> #REF! | H13: =COUNTIFS('Risk Register'!#REF!,"*"&C13&"*",'Risk Register'!M:M,"<=6") -> #REF!
B14: Physical | C14: PHY-012 | D14: Sanitation System Failure | E14: =COUNTIF('Risk Register'!#REF!,"*"&C14&"*") -> #REF! | F14: =COUNTIFS('Risk Register'!#REF!,"*"&C14&"*",'Risk Register'!M:M,">=16") -> #REF! | G14: =COUNTIFS('Risk Register'!#REF!,"*"&C14&"*",'Risk Register'!M:M,">=7",'Risk Register'!M:M,"<=15") -> #REF! | H14: =COUNTIFS('Risk Register'!#REF!,"*"&C14&"*",'Risk Register'!M:M,"<=6") -> #REF!
B15: Physical | C15: PHY-013 | D15: Natural Gas Distribution of Failure | E15: =COUNTIF('Risk Register'!#REF!,"*"&C15&"*") -> #REF! | F15: =COUNTIFS('Risk Register'!#REF!,"*"&C15&"*",'Risk Register'!M:M,">=16") -> #REF! | G15: =COUNTIFS('Risk Register'!#REF!,"*"&C15&"*",'Risk Register'!M:M,">=7",'Risk Register'!M:M,"<=15") -> #REF! | H15: =COUNTIFS('Risk Register'!#REF!,"*"&C15&"*",'Risk Register'!M:M,"<=6") -> #REF!
... B77: Technical | C77: TEC-041 | D77: Application Exploitation via Authentication Bypass | E77: =COUNTIF('Risk Register'!#REF!,"*"&C77&"*") -> #REF! | F77: =COUNTIFS('Risk Register'!#REF!,"*"&C77&"*",'Risk Register'!M:M,">=16") -> #REF! | G77: =COUNTIFS('Risk Register'!#REF!,"*"&C77&"*",'Risk Register'!M:M,">=7",'Risk Register'!M:M,"<=15") -> #REF! | H77: =COUNTIFS('Risk Register'!#REF!,"*"&C77&"*",'Risk Register'!M:M,"<=6") -> #REF!

Sheet Risk Register
B1: RISK REGISTER
B5: RISK ID | C5: SOURCE | D5: DATE Identified | E5: Risk Name | F5: Risk Description | G5: Framework Reference | H5: Likelihood | I5: SCORE Likelihood | J5: Impact | K5: SCORE Impact | L5: SCORE Risk | M5: Risk Rating | N5: Mitigation Plan | O5: Mitigation Milestones & Changes | P5: Point of Contact | Q5: Control(s) or Mitigation Action | R5: Control Reference | S5: Status | T5: DATE Status | U5: Review Needed?
B6: RR001 | H6: Probable | I6: =VLOOKUP(Tbl_RiskRegister[[#This Row],[Likelihood]],KEY!$G$3:$H$7,2,) -> 4 | J6: Critical Impact | K6: =VLOOKUP(Tbl_RiskRegister[[#This Row],[Impact]],KEY!$J$3:$K$7,2,0) -> 7 | L6: =Tbl_RiskRegister[[#This Row],[SCORE Likelihood]]*Tbl_RiskRegister[[#This Row],[SCORE Impact]] -> 28 | M6: =IF(Tbl_RiskRegister[[#This Row],[SCORE Risk]]<=7,"Low",(IF(Tbl_RiskRegister[[#This Row],[SCORE Risk]]<=19,"Medium",(IF(Tbl_RiskRegister[[#This Row],[SCORE Risk]]>19,"High","Error"))))) -> High | S6: Not Considered | U6: =IF(T6=0,"",(IF((TODAY()-T6)>365,"YES","No")))
B7: RR002 | H7: Probable | I7: =VLOOKUP(Tbl_RiskRegister[[#This Row],[Likelihood]],KEY!$G$3:$H$7,2,) -> 4 | J7: Substanative Impact | K7: =VLOOKUP(Tbl_RiskRegister[[#This Row],[Impact]],KEY!$J$3:$K$7,2,0) -> 5 | L7: =Tbl_RiskRegister[[#This Row],[SCORE Likelihood]]*Tbl_RiskRegister[[#This Row],[SCORE Impact]] -> 20 | M7: =IF(Tbl_RiskRegister[[#This Row],[SCORE Risk]]<=7,"Low",(IF(Tbl_RiskRegister[[#This Row],[SCORE Risk]]<=19,"Medium",(IF(Tbl_RiskRegister[[#This Row],[SCORE Risk]]>19,"High","Error"))))) -> High
B8: RR003 | H8: Possible | I8: =VLOOKUP(Tbl_RiskRegister[[#This Row],[Likelihood]],KEY!$G$3:$H$7,2,) -> 3 | J8: Substanative Impact | K8: =VLOOKUP(Tbl_RiskRegister[[#This Row],[Impact]],KEY!$J$3:$K$7,2,0) -> 5 | L8: =Tbl_RiskRegister[[#This Row],[SCORE Likelihood]]*Tbl_RiskRegister[[#This Row],[SCORE Impact]] -> 15 | M8: =IF(Tbl_RiskRegister[[#This Row],[SCORE Risk]]<=7,"Low",(IF(Tbl_RiskRegister[[#This Row],[SCORE Risk]]<=19,"Medium",(IF(Tbl_RiskRegister[[#This Row],[SCORE Risk]]>19,"High","Error"))))) -> Medium | S8: Not Considered
B9: RR004 | H9: Possible | I9: =VLOOKUP(Tbl_RiskRegister[[#This Row],[Likelihood]],KEY!$G$3:$H$7,2,) -> 3 | J9: Substanative Impact | K9: =VLOOKUP(Tbl_RiskRegister[[#This Row],[Impact]],KEY!$J$3:$K$7,2,0) -> 5 | L9: =Tbl_RiskRegister[[#This Row],[SCORE Likelihood]]*Tbl_RiskRegister[[#This Row],[SCORE Impact]] -> 15 | M9: =IF(Tbl_RiskRegister[[#This Row],[SCORE Risk]]<=7,"Low",(IF(Tbl_RiskRegister[[#This Row],[SCORE Risk]]<=19,"Medium",(IF(Tbl_RiskRegister[[#This Row],[SCORE Risk]]>19,"High","Error"))))) -> Medium
B10: RR005 | H10: Almost Certain | I10: =VLOOKUP(Tbl_RiskRegister[[#This Row],[Likelihood]],KEY!$G$3:$H$7,2,) -> 5 | J10: Substanative Impact | K10: =VLOOKUP(Tbl_RiskRegister[[#This Row],[Impact]],KEY!$J$3:$K$7,2,0) -> 5 | L10: =Tbl_RiskRegister[[#This Row],[SCORE Likelihood]]*Tbl_RiskRegister[[#This Row],[SCORE Impact]] -> 25 | M10: =IF(Tbl_RiskRegister[[#This Row],[SCORE Risk]]<=7,"Low",(IF(Tbl_RiskRegister[[#This Row],[SCORE Risk]]<=19,"Medium",(IF(Tbl_RiskRegister[[#This Row],[SCORE Risk]]>19,"High","Error"))))) -> High | N10: Develop, Approve IS Policy Education & Ack plan | O10: In Development | R10: CC 1.3.3 | S10: Deficient Controls | T10: 44411
B11: RR006 | H11: Possible | I11: =VLOOKUP(Tbl_RiskRegister[[#This Row],[Likelihood]],KEY!$G$3:$H$7,2,) -> 3 | J11: Substanative Impact | K11: =VLOOKUP(Tbl_RiskRegister[[#This Row],[Impact]],KEY!$J$3:$K$7,2,0) -> 5 | L11: =Tbl_RiskRegister[[#This Row],[SCORE Likelihood]]*Tbl_RiskRegister[[#This Row],[SCORE Impact]] -> 15 | M11: =IF(Tbl_RiskRegister[[#This Row],[SCORE Risk]]<=7,"Low",(IF(Tbl_RiskRegister[[#This Row],[SCORE Risk]]<=19,"Medium",(IF(Tbl_RiskRegister[[#This Row],[SCORE Risk]]>19,"High","Error"))))) -> Medium
B12: RR007 | H12: Possible | I12: =VLOOKUP(Tbl_RiskRegister[[#This Row],[Likelihood]],KEY!$G$3:$H$7,2,) -> 3 | J12: Substanative Impact | K12: =VLOOKUP(Tbl_RiskRegister[[#This Row],[Impact]],KEY!$J$3:$K$7,2,0) -> 5 | L12: =Tbl_RiskRegister[[#This Row],[SCORE Likelihood]]*Tbl_RiskRegister[[#This Row],[SCORE Impact]] -> 15 | M12: =IF(Tbl_RiskRegister[[#This Row],[SCORE Risk]]<=7,"Low",(IF(Tbl_RiskRegister[[#This Row],[SCORE Risk]]<=19,"Medium",(IF(Tbl_RiskRegister[[#This Row],[SCORE Risk]]>19,"High","Error"))))) -> Medium | N12: Define Logging/Auditing Plan Determine Retention Goals
B13: RR008 | H13: Possible | I13: =VLOOKUP(Tbl_RiskRegister[[#This Row],[Likelihood]],KEY!$G$3:$H$7,2,) -> 3 | J13: Substanative Impact | K13: =VLOOKUP(Tbl_RiskRegister[[#This Row],[Impact]],KEY!$J$3:$K$7,2,0) -> 5 | L13: =Tbl_RiskRegister[[#This Row],[SCORE Likelihood]]*Tbl_RiskRegister[[#This Row],[SCORE Impact]] -> 15 | M13: =IF(Tbl_RiskRegister[[#This Row],[SCORE Risk]]<=7,"Low",(IF(Tbl_RiskRegister[[#This Row],[SCORE Risk]]<=19,"Medium",(IF(Tbl_RiskRegister[[#This Row],[SCORE Risk]]>19,"High","Error"))))) -> Medium
B14: RR009 | H14: Possible | I14: =VLOOKUP(Tbl_RiskRegister[[#This Row],[Likelihood]],KEY!$G$3:$H$7,2,) -> 3 | J14: Substanative Impact | K14: =VLOOKUP(Tbl_RiskRegister[[#This Row],[Impact]],KEY!$J$3:$K$7,2,0) -> 5 | L14: =Tbl_RiskRegister[[#This Row],[SCORE Likelihood]]*Tbl_RiskRegister[[#This Row],[SCORE Impact]] -> 15 | M14: =IF(Tbl_RiskRegister[[#This Row],[SCORE Risk]]<=7,"Low",(IF(Tbl_RiskRegister[[#This Row],[SCORE Risk]]<=19,"Medium",(IF(Tbl_RiskRegister[[#This Row],[SCORE Risk]]>19,"High","Error"))))) -> Medium
B15: RR010 | H15: Possible | I15: =VLOOKUP(Tbl_RiskRegister[[#This Row],[Likelihood]],KEY!$G$3:$H$7,2,) -> 3 | J15: Substanative Impact | K15: =VLOOKUP(Tbl_RiskRegister[[#This Row],[Impact]],KEY!$J$3:$K$7,2,0) -> 5 | L15: =Tbl_RiskRegister[[#This Row],[SCORE Likelihood]]*Tbl_RiskRegister[[#This Row],[SCORE Impact]] -> 15 | M15: =IF(Tbl_RiskRegister[[#This Row],[SCORE Risk]]<=7,"Low",(IF(Tbl_RiskRegister[[#This Row],[SCORE Risk]]<=19,"Medium",(IF(Tbl_RiskRegister[[#This Row],[SCORE Risk]]>19,"High","Error"))))) -> Medium
B16: RR011 | H16: Possible | I16: =VLOOKUP(Tbl_RiskRegister[[#This Row],[Likelihood]],KEY!$G$3:$H$7,2,) -> 3 | J16: Substanative Impact | K16: =VLOOKUP(Tbl_RiskRegister[[#This Row],[Impact]],KEY!$J$3:$K$7,2,0) -> 5 | L16: =Tbl_RiskRegister[[#This Row],[SCORE Likelihood]]*Tbl_RiskRegister[[#This Row],[SCORE Impact]] -> 15 | M16: =IF(Tbl_RiskRegister[[#This Row],[SCORE Risk]]<=7,"Low",(IF(Tbl_RiskRegister[[#This Row],[SCORE Risk]]<=19,"Medium",(IF(Tbl_RiskRegister[[#This Row],[SCORE Risk]]>19,"High","Error"))))) -> Medium
B17: RR012 | H17: Possible | I17: =VLOOKUP(Tbl_RiskRegister[[#This Row],[Likelihood]],KEY!$G$3:$H$7,2,) -> 3 | J17: Substanative Impact | K17: =VLOOKUP(Tbl_RiskRegister[[#This Row],[Impact]],KEY!$J$3:$K$7,2,0) -> 5 | L17: =Tbl_RiskRegister[[#This Row],[SCORE Likelihood]]*Tbl_RiskRegister[[#This Row],[SCORE Impact]] -> 15 | M17: =IF(Tbl_RiskRegister[[#This Row],[SCORE Risk]]<=7,"Low",(IF(Tbl_RiskRegister[[#This Row],[SCORE Risk]]<=19,"Medium",(IF(Tbl_RiskRegister[[#This Row],[SCORE Risk]]>19,"High","Error"))))) -> Medium
B18: RR013 | H18: Possible | I18: =VLOOKUP(Tbl_RiskRegister[[#This Row],[Likelihood]],KEY!$G$3:$H$7,2,) -> 3 | J18: Substanative Impact | K18: =VLOOKUP(Tbl_RiskRegister[[#This Row],[Impact]],KEY!$J$3:$K$7,2,0) -> 5 | L18: =Tbl_RiskRegister[[#This Row],[SCORE Likelihood]]*Tbl_RiskRegister[[#This Row],[SCORE Impact]] -> 15 | M18: =IF(Tbl_RiskRegister[[#This Row],[SCORE Risk]]<=7,"Low",(IF(Tbl_RiskRegister[[#This Row],[SCORE Risk]]<=19,"Medium",(IF(Tbl_RiskRegister[[#This Row],[SCORE Risk]]>19,"High","Error"))))) -> Medium
B19: RR014 | H19: Possible | I19: =VLOOKUP(Tbl_RiskRegister[[#This Row],[Likelihood]],KEY!$G$3:$H$7,2,) -> 3 | J19: Substanative Impact | K19: =VLOOKUP(Tbl_RiskRegister[[#This Row],[Impact]],KEY!$J$3:$K$7,2,0) -> 5 | L19: =Tbl_RiskRegister[[#This Row],[SCORE Likelihood]]*Tbl_RiskRegister[[#This Row],[SCORE Impact]] -> 15 | M19: =IF(Tbl_RiskRegister[[#This Row],[SCORE Risk]]<=7,"Low",(IF(Tbl_RiskRegister[[#This Row],[SCORE Risk]]<=19,"Medium",(IF(Tbl_RiskRegister[[#This Row],[SCORE Risk]]>19,"High","Error"))))) -> Medium
B20: RR015 | H20: Possible | I20: =VLOOKUP(Tbl_RiskRegister[[#This Row],[Likelihood]],KEY!$G$3:$H$7,2,) -> 3 | J20: Substanative Impact | K20: =VLOOKUP(Tbl_RiskRegister[[#This Row],[Impact]],KEY!$J$3:$K$7,2,0) -> 5 | L20: =Tbl_RiskRegister[[#This Row],[SCORE Likelihood]]*Tbl_RiskRegister[[#This Row],[SCORE Impact]] -> 15 | M20: =IF(Tbl_RiskRegister[[#This Row],[SCORE Risk]]<=7,"Low",(IF(Tbl_RiskRegister[[#This Row],[SCORE Risk]]<=19,"Medium",(IF(Tbl_RiskRegister[[#This Row],[SCORE Risk]]>19,"High","Error"))))) -> Medium
B21: RR016 | H21: Possible | I21: =VLOOKUP(Tbl_RiskRegister[[#This Row],[Likelihood]],KEY!$G$3:$H$7,2,) -> 3 | J21: Substanative Impact | K21: =VLOOKUP(Tbl_RiskRegister[[#This Row],[Impact]],KEY!$J$3:$K$7,2,0) -> 5 | L21: =Tbl_RiskRegister[[#This Row],[SCORE Likelihood]]*Tbl_RiskRegister[[#This Row],[SCORE Impact]] -> 15 | M21: =IF(Tbl_RiskRegister[[#This Row],[SCORE Risk]]<=7,"Low",(IF(Tbl_RiskRegister[[#This Row],[SCORE Risk]]<=19,"Medium",(IF(Tbl_RiskRegister[[#This Row],[SCORE Risk]]>19,"High","Error"))))) -> Medium
B22: RR017 | H22: Possible | I22: =VLOOKUP(Tbl_RiskRegister[[#This Row],[Likelihood]],KEY!$G$3:$H$7,2,) -> 3 | J22: Substanative Impact | K22: =VLOOKUP(Tbl_RiskRegister[[#This Row],[Impact]],KEY!$J$3:$K$7,2,0) -> 5 | L22: =Tbl_RiskRegister[[#This Row],[SCORE Likelihood]]*Tbl_RiskRegister[[#This Row],[SCORE Impact]] -> 15 | M22: =IF(Tbl_RiskRegister[[#This Row],[SCORE Risk]]<=7,"Low",(IF(Tbl_RiskRegister[[#This Row],[SCORE Risk]]<=19,"Medium",(IF(Tbl_RiskRegister[[#This Row],[SCORE Risk]]>19,"High","Error"))))) -> Medium
B23: RR018 | H23: Possible | I23: =VLOOKUP(Tbl_RiskRegister[[#This Row],[Likelihood]],KEY!$G$3:$H$7,2,) -> 3 | J23: Substanative Impact | K23: =VLOOKUP(Tbl_RiskRegister[[#This Row],[Impact]],KEY!$J$3:$K$7,2,0) -> 5 | L23: =Tbl_RiskRegister[[#This Row],[SCORE Likelihood]]*Tbl_RiskRegister[[#This Row],[SCORE Impact]] -> 15 | M23: =IF(Tbl_RiskRegister[[#This Row],[SCORE Risk]]<=7,"Low",(IF(Tbl_RiskRegister[[#This Row],[SCORE Risk]]<=19,"Medium",(IF(Tbl_RiskRegister[[#This Row],[SCORE Risk]]>19,"High","Error"))))) -> Medium
B24: RR019 | H24: Possible | I24: =VLOOKUP(Tbl_RiskRegister[[#This Row],[Likelihood]],KEY!$G$3:$H$7,2,) -> 3 | J24: Substanative Impact | K24: =VLOOKUP(Tbl_RiskRegister[[#This Row],[Impact]],KEY!$J$3:$K$7,2,0) -> 5 | L24: =Tbl_RiskRegister[[#This Row],[SCORE Likelihood]]*Tbl_RiskRegister[[#This Row],[SCORE Impact]] -> 15 | M24: =IF(Tbl_RiskRegister[[#This Row],[SCORE Risk]]<=7,"Low",(IF(Tbl_RiskRegister[[#This Row],[SCORE Risk]]<=19,"Medium",(IF(Tbl_RiskRegister[[#This Row],[SCORE Risk]]>19,"High","Error"))))) -> Medium
... B55: RR050 | H55: Improbable | I55: =VLOOKUP(Tbl_RiskRegister[[#This Row],[Likelihood]],KEY!$G$3:$H$7,2,) -> 1 | J55: Substanative Impact | K55: =VLOOKUP(Tbl_RiskRegister[[#This Row],[Impact]],KEY!$J$3:$K$7,2,0) -> 5 | L55: =Tbl_RiskRegister[[#This Row],[SCORE Likelihood]]*Tbl_RiskRegister[[#This Row],[SCORE Impact]] -> 5 | M55: =IF(Tbl_RiskRegister[[#This Row],[SCORE Risk]]<=7,"Low",(IF(Tbl_RiskRegister[[#This Row],[SCORE Risk]]<=19,"Medium",(IF(Tbl_RiskRegister[[#This Row],[SCORE Risk]]>19,"High","Error"))))) -> Low
B57: Last Revised
B58: =TODAY() -> 44426

Sheet Controls Lib.
B1: CONTROLS Library
B5: Control ID | C5: Control Name | D5: Description | E5: Control TYPE | F5: Control FUNCTION | G5: Frequency | H5: Owner | I5: Evidence | J5: Risk Mapping | K5: Compliance Mapping | L5: Status | M5: DATE Implementation | N5: DATE Review or Validation | O5: Review Needed?
B6: VC001 | C6: Employee Handbook | D6: Personnel are reguired to read and accept the Employee Handbook upon hire. | E6: Administrative | F6: Preventative | G6: N/A | H6: HR | I6: Employee Handbook Signed Acknowledgements | J6: RR003 | K6: CC 1.1.1 | L6: Implemented | M6: 43494 | N6: 44343 | O6: =IF(Tbl_ControlLib[[#This Row],[DATE Review or Validation]]=0,"",(IF((TODAY()-Tbl_ControlLib[[#This Row],[DATE Review or Validation]])>365,"YES","No"))) -> No
B7: VC002 | O7: =IF(Tbl_ControlLib[[#This Row],[DATE Review or Validation]]=0,"",(IF((TODAY()-Tbl_ControlLib[[#This Row],[DATE Review or Validation]])>365,"YES","No")))
B8: VC003 | O8: =IF(Tbl_ControlLib[[#This Row],[DATE Review or Validation]]=0,"",(IF((TODAY()-Tbl_ControlLib[[#This Row],[DATE Review or Validation]])>365,"YES","No")))
B9: VC004 | O9: =IF(Tbl_ControlLib[[#This Row],[DATE Review or Validation]]=0,"",(IF((TODAY()-Tbl_ControlLib[[#This Row],[DATE Review or Validation]])>365,"YES","No")))
B10: VC005 | O10: =IF(Tbl_ControlLib[[#This Row],[DATE Review or Validation]]=0,"",(IF((TODAY()-Tbl_ControlLib[[#This Row],[DATE Review or Validation]])>365,"YES","No")))
B11: VC006 | O11: =IF(Tbl_ControlLib[[#This Row],[DATE Review or Validation]]=0,"",(IF((TODAY()-Tbl_ControlLib[[#This Row],[DATE Review or Validation]])>365,"YES","No")))
B12: VC007 | C12: IR Plan | D12: Incident Response plan is exercised and updated and/or reviewed annually | E12: Administrative | F12: Recovery | G12: 1yr | H12: SC | I12: IR Plan (with revision block) Notes/Lessons Learned for IR exercies | K12: CC 2.2.5 | L12: Draft | O12: =IF(Tbl_ControlLib[[#This Row],[DATE Review or Validation]]=0,"",(IF((TODAY()-Tbl_ControlLib[[#This Row],[DATE Review or Validation]])>365,"YES","No")))
B13: VC008 | C13: Risk Mgmt | D13: Risk Mgmt Policy and Risk Assessment/Mitigation tracking | E13: Administrative | F13: Preventative | G13: 1mo | H13: SC | I13: IS Policy Risk Register Monthly Agenda's | K13: CC 3.1.1 CC 3.1.2 | L13: Draft | O13: =IF(Tbl_ControlLib[[#This Row],[DATE Review or Validation]]=0,"",(IF((TODAY()-Tbl_ControlLib[[#This Row],[DATE Review or Validation]])>365,"YES","No")))
B14: VC009 | O14: =IF(Tbl_ControlLib[[#This Row],[DATE Review or Validation]]=0,"",(IF((TODAY()-Tbl_ControlLib[[#This Row],[DATE Review or Validation]])>365,"YES","No")))
B15: VC010 | O15: =IF(Tbl_ControlLib[[#This Row],[DATE Review or Validation]]=0,"",(IF((TODAY()-Tbl_ControlLib[[#This Row],[DATE Review or Validation]])>365,"YES","No")))
B16: VC011 | O16: =IF(Tbl_ControlLib[[#This Row],[DATE Review or Validation]]=0,"",(IF((TODAY()-Tbl_ControlLib[[#This Row],[DATE Review or Validation]])>365,"YES","No")))
B17: VC012 | O17: =IF(Tbl_ControlLib[[#This Row],[DATE Review or Validation]]=0,"",(IF((TODAY()-Tbl_ControlLib[[#This Row],[DATE Review or Validation]])>365,"YES","No")))
B18: VC013 | O18: =IF(Tbl_ControlLib[[#This Row],[DATE Review or Validation]]=0,"",(IF((TODAY()-Tbl_ControlLib[[#This Row],[DATE Review or Validation]])>365,"YES","No")))
B19: VC014 | O19: =IF(Tbl_ControlLib[[#This Row],[DATE Review or Validation]]=0,"",(IF((TODAY()-Tbl_ControlLib[[#This Row],[DATE Review or Validation]])>365,"YES","No")))
B20: VC015 | O20: =IF(Tbl_ControlLib[[#This Row],[DATE Review or Validation]]=0,"",(IF((TODAY()-Tbl_ControlLib[[#This Row],[DATE Review or Validation]])>365,"YES","No")))
B21: VC016 | O21: =IF(Tbl_ControlLib[[#This Row],[DATE Review or Validation]]=0,"",(IF((TODAY()-Tbl_ControlLib[[#This Row],[DATE Review or Validation]])>365,"YES","No")))
B22: VC017 | O22: =IF(Tbl_ControlLib[[#This Row],[DATE Review or Validation]]=0,"",(IF((TODAY()-Tbl_ControlLib[[#This Row],[DATE Review or Validation]])>365,"YES","No")))
B23: VC018 | O23: =IF(Tbl_ControlLib[[#This Row],[DATE Review or Validation]]=0,"",(IF((TODAY()-Tbl_ControlLib[[#This Row],[DATE Review or Validation]])>365,"YES","No")))
B24: VC019 | O24: =IF(Tbl_ControlLib[[#This Row],[DATE Review or Validation]]=0,"",(IF((TODAY()-Tbl_ControlLib[[#This Row],[DATE Review or Validation]])>365,"YES","No")))
B25: VC020 | O25: =IF(Tbl_ControlLib[[#This Row],[DATE Review or Validation]]=0,"",(IF((TODAY()-Tbl_ControlLib[[#This Row],[DATE Review or Validation]])>365,"YES","No")))
... B55: VC050 | O55: =IF(Tbl_ControlLib[[#This Row],[DATE Review or Validation]]=0,"",(IF((TODAY()-Tbl_ControlLib[[#This Row],[DATE Review or Validation]])>365,"YES","No")))
B57: Last Revised
B58: =TODAY() -> 44426

Sheet SOC Obj.
A1: TSC Ref. # | B1: TSC | C1: Points of Focus | D1: NIST CSF
A2: CC 1 | B2: CONTROL ENVIRONMENT
A3: CC 1.1 | B3: COSO Principle 1: The entity demonstrates a commitment to integrity and ethical values.
A4: CC 1.1.1 | C4: Sets the Tone at the Top—The board of directors and management, at all levels, demonstrate through their directives, actions, and behavior the importance of integrity and ethical values to support the functioning of the system of internal control. | D4: PR.AT-4
A5: CC 1.1.2 | C5: Establishes Standards of Conduct—The expectations of the board of directors and senior management concerning integrity and ethical values are defined in the entity’s standards of conduct and understood at all levels of the entity and by outsourced service providers and business partners.
A6: CC 1.1.3 | C6: Evaluates Adherence to Standards of Conduct—Processes are in place to evaluate the performance of individuals and teams against the entity’s expected standards of conduct.
A7: CC 1.1.4 | C7: Addresses Deviations in a Timely Manner—Deviations from the entity’s expected standards of conduct are identified and remedied in a timely and consistent manner.
A8: CC 1.1.5 | C8: Considers Contractors and Vendor Employees in Demonstrating Its Commitment—Management and the board of directors consider the use of contractors and vendor employees in its processes for establishing standards of conduct, evaluating adherence to those standards, and addressing deviations in a timely manner.
A9: CC 1.2 | B9: COSO Principle 2: The board of directors demonstrates independence from management and exercises oversight of the development and performance of internal control.
A10: CC 1.2.1 | C10: Establishes Oversight Responsibilities—The board of directors identifies and accepts its oversight responsibilities in relation to established requirements and expectations.
A11: CC 1.2.2 | C11: Applies Relevant Expertise—The board of directors defines, maintains, and periodically evaluates the skills and expertise needed among its members to enable them to ask probing questions of senior management and take commensurate action.
A12: CC 1.2.3 | C12: Operates Independently—The board of directors has sufficient members who are independent from management and objective in evaluations and decision making.
A13: CC 1.2.4 | C13: Supplements Board Expertise—The board of directors supplements its expertise relevant to security, availability, processing integrity, confidentiality, and privacy, as needed, through the use of a subcommittee or consultants.
A14: CC 1.3 | B14: COSO Principle 3: Management establishes, with board oversight, structures, reporting lines, and appropriate authorities and responsibilities in the pursuit of objectives.
A15: CC 1.3.1 | C15: Considers All Structures of the Entity—Management and the board of directors consider the multiple structures used (including operating units, legal entities, geographic distribution, and outsourced service providers) to support the achievement of objectives.
A16: CC 1.3.2 | C16: Establishes Reporting Lines—Management designs and evaluates lines of reporting for each entity structure to enable execution of authorities and responsibilities and flow of information to manage the activities of the entity.
A17: CC 1.3.3 | C17: Defines, Assigns, and Limits Authorities and Responsibilities—Management and the board of directors delegate authority, define responsibilities, and use appropriate processes and technology to assign responsibility and segregate duties as necessary at the various levels of the organization. | D17: ID.AM-6
A18: CC 1.3.4 | C18: Addresses Specific Requirements When Defining Authorities and Responsibilities—Management and the board of directors consider requirements relevant to security, availability, processing integrity, confidentiality, and privacy when defining authorities and responsibilities.
A19: CC 1.3.5 | C19: Considers Interactions With External Parties When Establishing Structures, Reporting Lines, Authorities, and Responsibilities—Management and the board of directors consider the need for the entity to interact with and monitor the activities of external parties when establishing structures, reporting lines, authorities, and responsibilities.
A20: CC 1.4 | B20: COSO Principle 4: The entity demonstrates a commitment to attract, develop, and retain competent individuals in alignment with objectives.
A21: CC 1.4.1 | C21: Establishes Policies and Practices—Policies and practices reflect expectations of competence necessary to support the achievement of objectives.
A22: CC 1.4.2 | C22: Evaluates Competence and Addresses Shortcomings—The board of directors and management evaluate competence across the entity and in outsourced service providers in relation to established policies and practices and act as necessary to address shortcomings.
A23: CC 1.4.3 | C23: Attracts, Develops, and Retains Individuals—The entity provides the mentoring and training needed to attract, develop, and retain sufficient and competent personnel and outsourced service providers to support the achievement of objectives.
A24: CC 1.4.4 | C24: Plans and Prepares for Succession—Senior management and the board of directors develop contingency plans for assignments of responsibility important for internal control.
A25: CC 1.4.5 | C25: Considers the Background of Individuals—The entity considers the background of potential and existing personnel, contractors, and vendor employees when determining whether to employ and retain the individuals. | D25: PR.IP-11
A26: CC 1.4.6 | C26: Considers the Technical Competency of Individuals—The entity considers the technical competency of potential and existing personnel, contractors, and vendor employees when determining whether to employ and retain the individuals.
A27: CC 1.4.7 | C27: Provides Training to Maintain Technical Competencies— The entity provides training programs, including continuing education and training, to ensure skill sets and technical competency of existing personnel, contractors, and vendor employees are developed and maintained.
A28: CC 1.5 | B28: COSO Principle 5: The entity holds individuals accountable for their internal control responsibilities in the pursuit of objectives.
A29: CC 1.5.1 | C29: Enforces Accountability Through Structures, Authorities, and Responsibilities—Management and the board of directors establish the mechanisms to communicate and hold individuals accountable for performance of internal control responsibilities across the entity and implement corrective action as necessary.
A30: CC 1.5.2 | C30: Establishes Performance Measures, Incentives, and Rewards—Management and the board of directors establish performance measures, incentives, and other rewards appropriate for responsibilities at all levels of the entity, reflecting appropriate dimensions of performance and expected standards of conduct, and considering the achievement of both short-term and longer-term objectives.
A31: CC 1.5.3 | C31: Evaluates Performance Measures, Incentives, and Rewards for Ongoing Relevance—Management and the board of directors align incentives and rewards with the fulfillment of internal control responsibilities in the achievement of objectives.
A32: CC 1.5.4 | C32: Considers Excessive Pressures—Management and the board of directors evaluate and adjust pressures associated with the achievement of objectives as they assign responsibilities, develop performance measures, and evaluate performance.
A33: CC 1.5.5 | C33: Evaluates Performance and Rewards or Disciplines Individuals—Management and the board of directors evaluate performance of internal control responsibilities, including adherence to standards of conduct and expected levels of competence, and provide rewards or exercise disciplinary action, as appropriate.
A34: CC 2 | B34: COMMUNICATION AND INFORMATION
A35: CC 2.1 | B35: COSO Principle 13: The entity obtains or generates and uses relevant, quality information to support the functioning of internal control.
A36: CC 2.1.1 | C36: Identifies Information Requirements—A process is in place to identify the information required and expected to support the functioning of the other components of internal control and the achievement of the entity’s objectives.
A37: CC 2.1.2 | C37: Captures Internal and External Sources of Data—Information systems capture internal and external sources of data.
A38: CC 2.1.3 | C38: Processes Relevant Data Into Information—Information systems process and transform relevant data into information.
A39: CC 2.1.4 | C39: Maintains Quality Throughout Processing—Information systems produce information that is timely, current, accurate, complete, accessible, protected, verifiable, and retained. Information is reviewed to assess its relevance in supporting the internal control components.
A40: CC 2.2 | B40: COSO Principle 14: The entity internally communicates information, including objectives and responsibilities for internal control, necessary to support the functioning of internal control.
...

Sheet AICPA TSC
A1: TSC REF | B1: Trust Services Criteria | C1: POINTS OF FOCUS | D1: NIST REF
B2: CONTROL ENVIRONMENT
A3: CC 1.1 | B3: COSO Principle 1: The entity demonstrates a commitment to integrity and ethical values.
A4: CC 1.1.1 | C4: Sets the Tone at the Top—The board of directors and management, at all levels, demonstrate through their directives, actions, and behavior the importance of integrity and ethical values to support the functioning of the system of internal control. | D4: PR.AT-4
A5: CC 1.1.2 | C5: Establishes Standards of Conduct—The expectations of the board of directors and senior management concerning integrity and ethical values are defined in the entity’s standards of conduct and understood at all levels of the entity and by outsourced service providers and business partners.
A6: CC 1.1.3 | C6: Evaluates Adherence to Standards of Conduct—Processes are in place to evaluate the performance of individuals and teams against the entity’s expected standards of conduct.
A7: CC 1.1.4 | C7: Addresses Deviations in a Timely Manner—Deviations from the entity’s expected standards of conduct are identified and remedied in a timely and consistent manner.
A8: CC 1.1.5 | C8: Considers Contractors and Vendor Employees in Demonstrating Its Commitment—Management and the board of directors consider the use of contractors and vendor employees in its processes for establishing standards of conduct, evaluating adherence to those standards, and addressing deviations in a timely manner.
A9: CC 1.2 | B9: COSO Principle 2: The board of directors demonstrates independence from management and exercises oversight of the development and performance of internal control.
A10: CC 1.2.1 | C10: Establishes Oversight Responsibilities—The board of directors identifies and accepts its oversight responsibilities in relation to established requirements and expectations.
A11: CC 1.2.2 | C11: Applies Relevant Expertise—The board of directors defines, maintains, and periodically evaluates the skills and expertise needed among its members to enable them to ask probing questions of senior management and take commensurate action.
A12: CC 1.2.3 | C12: Operates Independently—The board of directors has sufficient members who are independent from management and objective in evaluations and decision making.
A13: CC 1.2.4 | C13: Supplements Board Expertise—The board of directors supplements its expertise relevant to security, availability, processing integrity, confidentiality, and privacy, as needed, through the use of a subcommittee or consultants.
A14: CC 1.3 | B14: COSO Principle 3: Management establishes, with board oversight, structures, reporting lines, and appropriate authorities and responsibilities in the pursuit of objectives.
A15: CC 1.3.1 | C15: Considers All Structures of the Entity—Management and the board of directors consider the multiple structures used (including operating units, legal entities, geographic distribution, and outsourced service providers) to support the achievement of objectives.
A16: CC 1.3.2 | C16: Establishes Reporting Lines—Management designs and evaluates lines of reporting for each entity structure to enable execution of authorities and responsibilities and flow of information to manage the activities of the entity.
A17: CC 1.3.3 | C17: Defines, Assigns, and Limits Authorities and Responsibilities—Management and the board of directors delegate authority, define responsibilities, and use appropriate processes and technology to assign responsibility and segregate duties as necessary at the various levels of the organization. | D17: ID.AM-6
A18: CC 1.3.4 | C18: Addresses Specific Requirements When Defining Authorities and Responsibilities—Management and the board of directors consider requirements relevant to security, availability, processing integrity, confidentiality, and privacy when defining authorities and responsibilities.
A19: CC 1.3.5 | C19: Considers Interactions With External Parties When Establishing Structures, Reporting Lines, Authorities, and Responsibilities—Management and the board of directors consider the need for the entity to interact with and monitor the activities of external parties when establishing structures, reporting lines, authorities, and responsibilities.
A20: CC 1.4 | B20: COSO Principle 4: The entity demonstrates a commitment to attract, develop, and retain competent individuals in alignment with objectives.
A21: CC 1.4.1 | C21: Establishes Policies and Practices—Policies and practices reflect expectations of competence necessary to support the achievement of objectives.
A22: CC 1.4.2 | C22: Evaluates Competence and Addresses Shortcomings—The board of directors and management evaluate competence across the entity and in outsourced service providers in relation to established policies and practices and act as necessary to address shortcomings.
A23: CC 1.4.3 | C23: Attracts, Develops, and Retains Individuals—The entity provides the mentoring and training needed to attract, develop, and retain sufficient and competent personnel and outsourced service providers to support the achievement of objectives.
A24: CC 1.4.4 | C24: Plans and Prepares for Succession—Senior management and the board of directors develop contingency plans for assignments of responsibility important for internal control.
A25: CC 1.4.5 | C25: Considers the Background of Individuals—The entity considers the background of potential and existing personnel, contractors, and vendor employees when determining whether to employ and retain the individuals. | D25: PR.IP-11
A26: CC 1.4.6 | C26: Considers the Technical Competency of Individuals—The entity considers the technical competency of potential and existing personnel, contractors, and vendor employees when determining whether to employ and retain the individuals.
A27: CC 1.4.7 | C27: Provides Training to Maintain Technical Competencies— The entity provides training programs, including continuing education and training, to ensure skill sets and technical competency of existing personnel, contractors, and vendor employees are developed and maintained.
A28: CC 1.5 | B28: COSO Principle 5: The entity holds individuals accountable for their internal control responsibilities in the pursuit of objectives.
A29: CC 1.5.1 | C29: Enforces Accountability Through Structures, Authorities, and Responsibilities—Management and the board of directors establish the mechanisms to communicate and hold individuals accountable for performance of internal control responsibilities across the entity and implement corrective action as necessary.
A30: CC 1.5.2 | C30: Establishes Performance Measures, Incentives, and Rewards—Management and the board of directors establish performance measures, incentives, and other rewards appropriate for responsibilities at all levels of the entity, reflecting appropriate dimensions of performance and expected standards of conduct, and considering the achievement of both short-term and longer-term objectives.
A31: CC 1.5.3 | C31: Evaluates Performance Measures, Incentives, and Rewards for Ongoing Relevance—Management and the board of directors align incentives and rewards with the fulfillment of internal control responsibilities in the achievement of objectives.
A32: CC 1.5.4 | C32: Considers Excessive Pressures—Management and the board of directors evaluate and adjust pressures associated with the achievement of objectives as they assign responsibilities, develop performance measures, and evaluate performance.
A33: CC 1.5.5 | C33: Evaluates Performance and Rewards or Disciplines Individuals—Management and the board of directors evaluate performance of internal control responsibilities, including adherence to standards of conduct and expected levels of competence, and provide rewards or exercise disciplinary action, as appropriate.
B34: COMMUNICATION AND INFORMATION
A35: CC2.1 | B35: COSO Principle 13: The entity obtains or generates and uses relevant, quality information to support the functioning of internal control.
C36: Identifies Information Requirements—A process is in place to identify the information required and expected to support the functioning of the other components of internal control and the achievement of the entity’s objectives.
C37: Captures Internal and External Sources of Data—Information systems capture internal and external sources of data.
C38: Processes Relevant Data Into Information—Information systems process and transform relevant data into information.
C39: Maintains Quality Throughout Processing—Information systems produce information that is timely, current, accurate, complete, accessible, protected, verifiable, and retained. Information is reviewed to assess its relevance in supporting the internal control components.
A40: CC2.2 | B40: COSO Principle 14: The entity internally communicates information, including objectives and responsibilities for internal control, necessary to support the functioning of internal control.
...

Sheet NIST CSF
A1: Sort | B1: Function | C1: Function Desc. | D1: Category | E1: Category Desc. | F1: Subcategory | G1: SubCategory Desc. | H1: Ref: CIS | I1: Ref: ISO | J1: Ref: 800-53 R4 | K1: Ref: HIPAA | L1: Ref: HITRUST | M1: Ref: COBIT 5
A2: 1.1.1 | B2: ID | C2: Identify | D2: AM | E2: Asset Management (ID.AM): The data, personnel, devices, systems, and facilities that enable the organization to achieve business purposes are identified and managed consistent with their relative importance to organizational objectives and the organization’s risk strategy. | F2: ID.AM-1 | G2: Physical devices and systems within the organization are inventoried | H2: CIS CSC 1 | I2: A.8.1.1, A.8.1.2 | J2: CM-8, PM-5 | K2: 45 C.F.R. §§ 164.308(a)(1)(ii)(A), 164.310(a)(2)(ii), 164.310(d) | M2: BAI09.01, BAI09.02
A3: 1.1.2 | B3: ID | C3: Identify | D3: AM | E3: Asset Management (ID.AM): The data, personnel, devices, systems, and facilities that enable the organization to achieve business purposes are identified and managed consistent with their relative importance to organizational objectives and the organization’s risk strategy. | F3: ID.AM-2 | G3: Software platforms and applications within the organization are inventoried | H3: CIS CSC 2 | I3: A.8.1.1, A.8.1.2 | J3: CM-8, PM-5 | K3: 45 C.F.R. §§ 164.308(a)(1)(ii)(A), 164.308(a)(7)(ii)(E ) | M3: BAI09.01, BAI09.02, BAI09.05
A4: 1.1.3 | B4: ID | C4: Identify | D4: AM | E4: Asset Management (ID.AM): The data, personnel, devices, systems, and facilities that enable the organization to achieve business purposes are identified and managed consistent with their relative importance to organizational objectives and the organization’s risk strategy. | F4: ID.AM-3 | G4: Organizational communication and data flows are mapped | H4: CIS CSC 12 | I4: A.13.2.1 | J4: AC-4, CA-3, CA-9, PL-8 | K4: 45 C.F.R. §§ 164.308(a)(1)(ii)(A), 164.308(a)(3)(ii)(A), 164.308(a)(8), 164.310(d) | M4: DSS05.02
A5: 1.1.4 | B5: ID | C5: Identify | D5: AM | E5: Asset Management (ID.AM): The data, personnel, devices, systems, and facilities that enable the organization to achieve business purposes are identified and managed consistent with their relative importance to organizational objectives and the organization’s risk strategy. | F5: ID.AM-4 | G5: External information systems are catalogued | H5: CIS CSC 12 | I5: A.11.2.6 | J5: AC-20, SA-9 | K5: 45 C.F.R. §§ 164.308(a)(4)(ii)(A), 164.308(b), 164.314(a)(1), 164.314(a)(2)(i)(B), 164.314(a)(2)(ii), 164.316(b)(2) | M5: APO02.02
A6: 1.1.5 | B6: ID | C6: Identify | D6: AM | E6: Asset Management (ID.AM): The data, personnel, devices, systems, and facilities that enable the organization to achieve business purposes are identified and managed consistent with their relative importance to organizational objectives and the organization’s risk strategy. | F6: ID.AM-5 | G6: Resources (e.g., hardware, devices, data, time, personnel, and software) are prioritized based on their classification, criticality, and business value | H6: CIS CSC 13, 14 | I6: A.8.2.1 | J6: CP-2, RA-2, SA-14, SC-6 | K6: 45 C.F.R. § 164.308(a)(7)(ii)(E ) | M6: APO03.03, APO03.04, BAI09.02
A7: 1.1.6 | B7: ID | C7: Identify | D7: AM | E7: Asset Management (ID.AM): The data, personnel, devices, systems, and facilities that enable the organization to achieve business purposes are identified and managed consistent with their relative importance to organizational objectives and the organization’s risk strategy. | F7: ID.AM-6 | G7: Cybersecurity roles and responsibilities for the entire workforce and third-party stakeholders (e.g., suppliers, customers, partners) are established | H7: CIS CSC 17, 19 | I7: A.6.1.1 | J7: CP-2, PS-7, PM-11 | K7: 45 C.F.R. §§ 164.308(a)(2), 164.308(a)(3), 164.308(a)(4), 164.308(b)(1), 164.314 | M7: APO01.02, DSS06.03
A8: 1.2.1 | B8: ID | C8: Identify | D8: BE | E8: Business Environment (ID.BE): The organization’s mission, objectives, stakeholders, and activities are understood and prioritized; this information is used to inform cybersecurity roles, responsibilities, and risk management decisions. | F8: ID.BE-1 | G8: The organization’s role in the supply chain is identified and communicated | I8: A.15.1.3, A.15.2.1, A.15.2.2 | J8: CP-2, SA-12 | K8: 45 C.F.R. §§ 164.308(a)(1)(ii)(A), 164.308(a)(4)(ii), 164.308(a)(7)(ii)(C), 164.308(a)(7)(ii)(E), 164.308(a)(8), 164.310(a)(2)(i), 164.314, 164.316 | M8: APO08.04, APO08.05, APO10.03, APO10.04, APO10.05
A9: 1.2.2 | B9: ID | C9: Identify | D9: BE | E9: Business Environment (ID.BE): The organization’s mission, objectives, stakeholders, and activities are understood and prioritized; this information is used to inform cybersecurity roles, responsibilities, and risk management decisions. | F9: ID.BE-2 | G9: The organization’s place in critical infrastructure and its industry sector is identified and communicated | J9: PM-8 | K9: 45 C.F.R. §§ 164.308(a)(1)(ii)(A), 164.308(a)(4)(ii), 164.308(a)(7)(ii)(C), 164.308(a)(7)(ii)(E), 164.308(a)(8), 164.310(a)(2)(i), 164.314, 164.316 | M9: APO02.06, APO03.01
A10: 1.2.3 | B10: ID | C10: Identify | D10: BE | E10: Business Environment (ID.BE): The organization’s mission, objectives, stakeholders, and activities are understood and prioritized; this information is used to inform cybersecurity roles, responsibilities, and risk management decisions. | F10: ID.BE-3 | G10: Priorities for organizational mission, objectives, and activities are established and communicated | J10: PM-11, SA-14 | K10: 45 C.F.R. §§ 164.308(a)(7)(ii)(B), 164.308(a)(7)(ii)(C), 164.308(a)(7)(ii)(D),164.308(a)(7)(ii)(E), 164.310(a)(2)(i), 164.316 | M10: APO02.01, APO02.06, APO03.01
A11: 1.2.4 | B11: ID | C11: Identify | D11: BE | E11: Business Environment (ID.BE): The organization’s mission, objectives, stakeholders, and activities are understood and prioritized; this information is used to inform cybersecurity roles, responsibilities, and risk management decisions. | F11: ID.BE-4 | G11: Dependencies and critical functions for delivery of critical services are established | I11: A.11.2.2, A.11.2.3, A.12.1.3 | J11: CP-8, PE-9, PE-11, PM-8, SA-14 | K11: 45 C.F.R. §§ 164.308(a)(7)(i), 164.308.(a)(7)(ii)(E), 164.310(a)(2)(i), 164.312(a)(2)(ii), 164.314(a)(1), 164.314(b)(2)(i)
A12: 1.2.5 | B12: ID | C12: Identify | D12: BE | E12: Business Environment (ID.BE): The organization’s mission, objectives, stakeholders, and activities are understood and prioritized; this information is used to inform cybersecurity roles, responsibilities, and risk management decisions. | F12: ID.BE-5 | G12: Resilience requirements to support delivery of critical services are established for all operating states (e.g. under duress/attack, during recovery, normal operations) | I12: A.11.1.4, A.17.1.1, A.17.1.2, A.17.2.1 | J12: CP-2, CP-11, SA-13, SA-14 | K12: 45 C.F.R. §§ 164.308(a)(1)(ii)(B), 164.308(a)(6)(ii), 164.308(a)(7), 164.308(a)(8), 164.310(a)(2)(i), 164.312(a)(2)(ii), 164.314(b)(2)(i) | M12: DSS04.02
A13: 1.3.1 | B13: ID | C13: Identify | D13: GV | E13: Governance (ID.GV): The policies, procedures, and processes to manage and monitor the organization’s regulatory, legal, risk, environmental, and operational requirements are understood and inform the management of cybersecurity risk. | F13: ID.GV-1 | G13: Organizational cybersecurity policy is established and communicated | H13: CIS CSC 19 | I13: A.5.1.1 | J13: -1 controls from all security control families | K13: 45 C.F.R. §§ 164.308(a)(1)(i), 164.316 | M13: APO01.03, EDM01.01, EDM01.02
A14: 1.3.2 | B14: ID | C14: Identify | D14: GV | E14: Governance (ID.GV): The policies, procedures, and processes to manage and monitor the organization’s regulatory, legal, risk, environmental, and operational requirements are understood and inform the management of cybersecurity risk. | F14: ID.GV-2 | G14: Cybersecurity roles and responsibilities are coordinated and aligned with internal roles and external partners | H14: CIS CSC 19 | I14: A.6.1.1, A.7.2.1 | J14: PS-7, PM-1, PM-2 | K14: 45 C.F.R. §§ 164.308(a)(1)(i), 164.308(a)(2), 164.308(a)(3), 164.308(a)(4), 164.308(b), 164.314 | M14: APO13.12
A15: 1.3.3 | B15: ID | C15: Identify | D15: GV | E15: Governance (ID.GV): The policies, procedures, and processes to manage and monitor the organization’s regulatory, legal, risk, environmental, and operational requirements are understood and inform the management of cybersecurity risk. | F15: ID.GV-3 | G15: Legal and regulatory requirements regarding cybersecurity, including privacy and civil liberties obligations, are understood and managed | H15: CIS CSC 19 | I15: A.18.1 | J15: -1 controls from all security control families | K15: 45 C.F.R. §§ 164.306, 164.308, 164.310, 164.312, 164.314, 164.316 | M15: MEA03.01, MEA03.04
A16: 1.3.4 | B16: ID | C16: Identify | D16: GV | E16: Governance (ID.GV): The policies, procedures, and processes to manage and monitor the organization’s regulatory, legal, risk, environmental, and operational requirements are understood and inform the management of cybersecurity risk. | F16: ID.GV-4 | G16: Governance and risk management processes address cybersecurity risks | J16: SA-2, PM-3, PM-7, PM-9, PM-10, PM-11 | K16: 45 C.F.R. §§ 164.308(a)(1), 164.308(b) | M16: DSS04.02
A17: 1.4.1 | B17: ID | C17: Identify | D17: RA | E17: Risk Assessment (ID.RA): The organization understands the cybersecurity risk to organizational operations (including mission, functions, image, or reputation), organizational assets, and individuals. | F17: ID.RA-1 | G17: Asset vulnerabilities are identified and documented | H17: CIS CSC 4 | I17: A.12.6.1, A.18.2.3 | J17: CA-2, CA-7, CA-8, RA-3, RA-5, SA-5, SA-11, SI-2, SI-4, SI-5 | K17: 45 C.F.R. §§ 164.308(a)(1)(ii)(A), 164.308(a)(7)(ii)(E), 164.308(a)(8), 164.310(a)(1), 164.312(a)(1), 164.316(b)(2)(iii) | M17: APO12.01, APO12.02, APO12.03, APO12.04
A18: 1.4.2 | B18: ID | C18: Identify | D18: RA | E18: Risk Assessment (ID.RA): The organization understands the cybersecurity risk to organizational operations (including mission, functions, image, or reputation), organizational assets, and individuals. | F18: ID.RA-2 | G18: Cyber threat intelligence is received from information sharing forums and sources. | H18: CIS CSC 4 | I18: A.6.1.4 | J18: SI-5, PM-15, PM-16
A19: 1.4.3 | B19: ID | C19: Identify | D19: RA | E19: Risk Assessment (ID.RA): The organization understands the cybersecurity risk to organizational operations (including mission, functions, image, or reputation), organizational assets, and individuals. | F19: ID.RA-3 | G19: Threats, both internal and external, are identified and documented | H19: CIS CSC 4 | J19: RA-3, SI-5, PM-12, PM-16 | K19: 45 C.F.R. §§ 164.308(a)(1)(ii)(A),164.308(a)(1)(ii)(D), 164.308(a)(3), 164.308(a)(4), 164.308(a)(5)(ii)(A),164.310(a)(1), 164.310(a)(2)(iii), 164.312(a)(1), 164.312(c), 164.312(e), 164.314, 164.316 | M19: APO12.01, APO12.02, APO12.03, APO12.04
A20: 1.4.4 | B20: ID | C20: Identify | D20: RA | E20: Risk Assessment (ID.RA): The organization understands the cybersecurity risk to organizational operations (including mission, functions, image, or reputation), organizational assets, and individuals. | F20: ID.RA-4 | G20: Potential business impacts and likelihoods are identified | H20: CIS CSC 4 | J20: RA-2, RA-3, SA-14, PM-9, PM-11 | K20: 45 C.F.R. §§ 164.308(a)(1)(i), 164.308(a)(1)(ii)(A), 164.308(a)(1)(ii)(B), 164.308(a)(6), 164.308(a)(7)(ii)(E), 164.308(a)(8), 164.316(a) | M20: DSS04.02
A21: 1.4.5 | B21: ID | C21: Identify | D21: RA | E21: Risk Assessment (ID.RA): The organization understands the cybersecurity risk to organizational operations (including mission, functions, image, or reputation), organizational assets, and individuals. | F21: ID.RA-5 | G21: Threats, vulnerabilities, likelihoods, and impacts are used to determine risk | H21: CIS CSC 4 | I21: A.12.6.1 | J21: RA-2, RA-3, PM-16 | K21: 45 C.F.R. §§ 164.308(a)(1)(ii)(A), 164.308(a)(1)(ii)(B), 164.308(a)(1)(ii)(D), 164.308(a)(7)(ii)(D), 164.308(a)(7)(ii)(E), 164.316(a) | M21: APO12.02
A22: 1.4.6 | B22: ID | C22: Identify | D22: RA | E22: Risk Assessment (ID.RA): The organization understands the cybersecurity risk to organizational operations (including mission, functions, image, or reputation), organizational assets, and individuals. | F22: ID.RA-6 | G22: Risk responses are identified and prioritized | H22: CIS CSC 4 | J22: PM-4, PM-9 | K22: 45 C.F.R. §§ 164.308(a)(1)(ii)(B), 164.314(a)(2)(i)(C), 164.314(b)(2)(iv) | M22: APO12.05, APO13.02
A23: 1.5.1 | B23: ID | C23: Identify | D23: RM | E23: Risk Management Strategy (ID.RM): The organization’s priorities, constraints, risk tolerances, and assumptions are established and used to support operational risk decisions. | F23: ID.RM-1 | G23: Risk management processes are established, managed, and agreed to by organizational stakeholders | H23: CIS CSC 4 | J23: PM-9 | K23: 45 C.F.R. § 164.308(a)(1)(ii)(B) | M23: APO12.04, APO12.05, APO13.02, BAI02.03, BAI04.02
A24: 1.5.2 | B24: ID | C24: Identify | D24: RM | E24: Risk Management Strategy (ID.RM): The organization’s priorities, constraints, risk tolerances, and assumptions are established and used to support operational risk decisions. | F24: ID.RM-2 | G24: Organizational risk tolerance is determined and clearly expressed | J24: PM-9 | K24: 45 C.F.R. § 164.308(a)(1)(ii)(B) | M24: APO12.06
A25: 1.5.3 | B25: ID | C25: Identify | D25: RM | E25: Risk Management Strategy (ID.RM): The organization’s priorities, constraints, risk tolerances, and assumptions are established and used to support operational risk decisions. | F25: ID.RM-3 | G25: The organization’s determination of risk tolerance is informed by its role in critical infrastructure and sector specific risk analysis | J25: SA-14, PM-8, PM-9, PM-11 | K25: 45 C.F.R. §§ 164.308(a)(1)(ii)(B), 164.308(a)(6)(ii), 164.308(a)(7)(i), 164.308(a)(7)(ii)(C),164.308(a)(7)(ii)(E), 164.310(a)(2)(i)
A26: 1.6.1 | B26: ID | C26: Identify | D26: SC | E26: Supply Chain Risk Management (ID.SC): The organization’s priorities, constraints, risk tolerances, and assumptions are established and used to support risk decisions associated with managing supply chain risk. The organization has established and implemented the processes to identify, assess and manage supply chain risks. | F26: ID.SC-1 | G26: Cyber supply chain risk management processes are identified, established, assessed, managed, and agreed to by organizational stakeholders | H26: CIS CSC 4 | I26: A.9.2.1, A.9.2.2, A.9.2.4, A.9.3.1, A.9.4.2, A.9.4.3 | J26: SA-9, SA-12, PM-9 | M26: DSS05.04, DSS06.03
A27: 1.6.2 | B27: ID | C27: Identify | D27: SC | E27: Supply Chain Risk Management (ID.SC): The organization’s priorities, constraints, risk tolerances, and assumptions are established and used to support risk decisions associated with managing supply chain risk. The organization has established and implemented the processes to identify, assess and manage supply chain risks. | F27: ID.SC-2 | G27: Suppliers and third party partners of information systems, components, and services are identified, prioritized, and assessed using a cyber supply chain risk assessment process | I27: A.11.1.1, A.11.1.2, A.11.1.4, A.11.1.6, A.11.2.3 | J27: RA-2, RA-3, SA-12, SA-14, SA-15, PM-9 | M27: DSS01.04, DSS05.05
A28: 1.6.3 | B28: ID | C28: Identify | D28: SC | E28: Supply Chain Risk Management (ID.SC): The organization’s priorities, constraints, risk tolerances, and assumptions are established and used to support risk decisions associated with managing supply chain risk. The organization has established and implemented the processes to identify, assess and manage supply chain risks. | F28: ID.SC-3 | G28: Contracts with suppliers and third-party partners are used to implement appropriate measures designed to meet the objectives of an organization’s cybersecurity program and Cyber Supply Chain Risk Management Plan. | I28: A.6.2.2, A.13.1.1, A.13.2.1 | J28: SA-9, SA-11, SA-12, PM-9 | M28: APO13.01, DSS01.04, DSS05.03
A29: 1.6.4 | B29: ID | C29: Identify | D29: SC | E29: Supply Chain Risk Management (ID.SC): The organization’s priorities, constraints, risk tolerances, and assumptions are established and used to support risk decisions associated with managing supply chain risk. The organization has established and implemented the processes to identify, assess and manage supply chain risks. | F29: ID.SC-4 | G29: Suppliers and third-party partners are routinely assessed using audits, test results, or other forms of evaluations to confirm they are meeting their contractual obligations. | I29: A.6.1.2, A.9.1.2, A.9.2.3, A.9.4.1, A.9.4.4 | J29: AU-2, AU-6, AU-12, AU-16, PS-7, SA-9, SA-12
A30: 1.6.5 | B30: ID | C30: Identify | D30: SC | E30: Supply Chain Risk Management (ID.SC): The organization’s priorities, constraints, risk tolerances, and assumptions are established and used to support risk decisions associated with managing supply chain risk. The organization has established and implemented the processes to identify, assess and manage supply chain risks. | F30: ID.SC-5 | G30: Response and recovery planning and testing are conducted with suppliers and third-party providers | H30: CIS CSC 19, 20 | I30: A.13.1.1, A.13.1.3, A.13.2.1 | J30: CP-2, CP-4, IR-3, IR-4, IR-6, IR-8, IR-9
A31: 2.1.1 | B31: PR | C31: Protect | D31: AC | E31: Identity Management, Authentication and Access Control (PR.AC): Access to physical and logical assets and associated facilities is limited to authorized users, processes, and devices, and is managed consistent with the assessed risk of unauthorized access to authorized activities and transactions. | F31: PR.AC-1 | G31: Identities and credentials are issued, managed, verified, revoked, and audited for authorized devices, users and processes | H31: CIS CSC 1, 5, 15, 16 | I31: A.7.2.2 | J31: AC-1, AC-2, IA-1, IA-2, IA-3, IA-4, IA-5, IA-6, IA-7, IA-8, IA-9, IA-10, IA-11 | K31: 45 C.F.R. §§ 164.308(a)(3)(ii)(B), 164.308(a)(3)(ii)(C), 164.308(a)(4)(i), 164.308(a)(4)(ii)(B), 164.308(a)(4)(ii)(C ), 164.312(a)(2)(i), 164.312(a)(2)(ii),164.312(a)(2)(iii), 164.312(d) | M31: APO07.03, BAI05.07
A32: 2.1.2 | B32: PR | C32: Protect | D32: AC | E32: Identity Management, Authentication and Access Control (PR.AC): Access to physical and logical assets and associated facilities is limited to authorized users, processes, and devices, and is managed consistent with the assessed risk of unauthorized access to authorized activities and transactions. | F32: PR.AC-2 | G32: Physical access to assets is managed and protected | I32: A.6.1.1, A.7.2.2 | J32: PE-2, PE-3, PE-4, PE-5, PE-6, PE-8 | K32: 45 C.F.R. §§ 164.308(a)(1)(ii)(B), 164.308(a)(7)(i), 164.308(a)(7)(ii)(A), 164.310(a)(1), 164.310(a)(2)(i), 164.310(a)(2)(ii), 164.310(a)(2)(iii), 164.310(b), 164.310(c), 164.310(d)(1), 164.310(d)(2)(iii) | M32: APO07.02, DSS06.03
